Workbook
Name G1_Data: OFFSET(INDEX(data!$E:$E,MATCH(report!$B$5,data!$E:$E,0)),-1,(report!$H$5-5)-(report!$B$7-1),1,report!$B$7)
Name G1_Lie: OFFSET(INDEX(data!$E:$E,MATCH(report!$B$5,data!$E:$E,0)),-3,(report!$H$5-5)-(report!$B$7-1),1,report!$B$7)
Name G1_Lse: OFFSET(INDEX(data!$E:$E,MATCH(report!$B$5,data!$E:$E,0)),-2,(report!$H$5-5)-(report!$B$7-1),1,report!$B$7)
Name G1_Nominal: OFFSET(INDEX(data!$E:$E,MATCH(report!$B$5,data!$E:$E,0)),-4,(report!$H$5-5)-(report!$B$7-1),1,report!$B$7)
Name G1_XValues: OFFSET(INDEX(data!$E:$E,MATCH(report!$B$5,data!$E:$E,0)),-6,(report!$H$5-5)-(report!$B$7-1),2,report!$B$7)
Name G10_Data: OFFSET(INDEX(data!$E:$E,MATCH(report!$B$50,data!$E:$E,0)),-1,(report!$H$50-5)-(report!$B$52-1),1,report!$B$52)
Name G10_Lie: OFFSET(INDEX(data!$E:$E,MATCH(report!$B$50,data!$E:$E,0)),-3,(report!$H$50-5)-(report!$B$52-1),1,report!$B$52)
Name G10_Lse: OFFSET(INDEX(data!$E:$E,MATCH(report!$B$50,data!$E:$E,0)),-2,(report!$H$50-5)-(report!$B$52-1),1,report!$B$52)
Name G10_Nominal: OFFSET(INDEX(data!$E:$E,MATCH(report!$B$50,data!$E:$E,0)),-4,(report!$H$50-5)-(report!$B$52-1),1,report!$B$52)
Name G10_XValues: OFFSET(INDEX(data!$E:$E,MATCH(report!$B$50,data!$E:$E,0)),-6,(report!$H$50-5)-(report!$B$52-1),2,report!$B$52)
Name G11_Data: OFFSET(INDEX(data!$E:$E,MATCH(report!$B$55,data!$E:$E,0)),-1,(report!$H$55-5)-(report!$B$57-1),1,report!$B$57)
Name G11_Lie: OFFSET(INDEX(data!$E:$E,MATCH(report!$B$55,data!$E:$E,0)),-3,(report!$H$55-5)-(report!$B$57-1),1,report!$B$57)
Name G11_Lse: OFFSET(INDEX(data!$E:$E,MATCH(report!$B$55,data!$E:$E,0)),-2,(report!$H$55-5)-(report!$B$57-1),1,report!$B$57)
Name G11_Nominal: OFFSET(INDEX(data!$E:$E,MATCH(report!$B$55,data!$E:$E,0)),-4,(report!$H$55-5)-(report!$B$57-1),1,report!$B$57)
Name G11_XValues: OFFSET(INDEX(data!$E:$E,MATCH(report!$B$55,data!$E:$E,0)),-6,(report!$H$55-5)-(report!$B$57-1),2,report!$B$57)
Name G12_Data: OFFSET(INDEX(data!$E:$E,MATCH(report!$B$60,data!$E:$E,0)),-1,(report!$H$60-5)-(report!$B$62-1),1,report!$B$62)
Name G12_Lie: OFFSET(INDEX(data!$E:$E,MATCH(report!$B$60,data!$E:$E,0)),-3,(report!$H$60-5)-(report!$B$62-1),1,report!$B$62)
Name G12_Lse: OFFSET(INDEX(data!$E:$E,MATCH(report!$B$60,data!$E:$E,0)),-2,(report!$H$60-5)-(report!$B$62-1),1,report!$B$62)
Name G12_Nominal: OFFSET(INDEX(data!$E:$E,MATCH(report!$B$60,data!$E:$E,0)),-4,(report!$H$60-5)-(report!$B$62-1),1,report!$B$62)
Name G12_XValues: OFFSET(INDEX(data!$E:$E,MATCH(report!$B$60,data!$E:$E,0)),-6,(report!$H$60-5)-(report!$B$62-1),2,report!$B$62)
Name G13_Data: OFFSET(INDEX(data!$E:$E,MATCH(report!$B$65,data!$E:$E,0)),-1,(report!$H$65-5)-(report!$B$67-1),1,report!$B$67)
Name G13_Lie: OFFSET(INDEX(data!$E:$E,MATCH(report!$B$65,data!$E:$E,0)),-3,(report!$H$65-5)-(report!$B$67-1),1,report!$B$67)
Name G13_Lse: OFFSET(INDEX(data!$E:$E,MATCH(report!$B$65,data!$E:$E,0)),-2,(report!$H$65-5)-(report!$B$67-1),1,report!$B$67)
Name G13_Nominal: OFFSET(INDEX(data!$E:$E,MATCH(report!$B$65,data!$E:$E,0)),-4,(report!$H$65-5)-(report!$B$67-1),1,report!$B$67)
Name G13_XValues: OFFSET(INDEX(data!$E:$E,MATCH(report!$B$65,data!$E:$E,0)),-6,(report!$H$65-5)-(report!$B$67-1),2,report!$B$67)
Name G14_Data: OFFSET(INDEX(data!$E:$E,MATCH(report!$B$70,data!$E:$E,0)),-1,(report!$H$70-5)-(report!$B$72-1),1,report!$B$72)
Name G14_Lie: OFFSET(INDEX(data!$E:$E,MATCH(report!$B$70,data!$E:$E,0)),-3,(report!$H$70-5)-(report!$B$72-1),1,report!$B$72)
Name G14_Lse: OFFSET(INDEX(data!$E:$E,MATCH(report!$B$70,data!$E:$E,0)),-2,(report!$H$70-5)-(report!$B$72-1),1,report!$B$72)
Name G14_Nominal: OFFSET(INDEX(data!$E:$E,MATCH(report!$B$70,data!$E:$E,0)),-4,(report!$H$70-5)-(report!$B$72-1),1,report!$B$72)
Name G14_XValues: OFFSET(INDEX(data!$E:$E,MATCH(report!$B$70,data!$E:$E,0)),-6,(report!$H$70-5)-(report!$B$72-1),2,report!$B$72)
Name G15_Data: OFFSET(INDEX(data!$E:$E,MATCH(report!$B$75,data!$E:$E,0)),-1,(report!$H$75-5)-(report!$B$77-1),1,report!$B$77)
Name G15_Lie: OFFSET(INDEX(data!$E:$E,MATCH(report!$B$75,data!$E:$E,0)),-3,(report!$H$75-5)-(report!$B$77-1),1,report!$B$77)
Name G15_Lse: OFFSET(INDEX(data!$E:$E,MATCH(report!$B$75,data!$E:$E,0)),-2,(report!$H$75-5)-(report!$B$77-1),1,report!$B$77)
Name G15_Nominal: OFFSET(INDEX(data!$E:$E,MATCH(report!$B$75,data!$E:$E,0)),-4,(report!$H$75-5)-(report!$B$77-1),1,report!$B$77)
Name G15_XValues: OFFSET(INDEX(data!$E:$E,MATCH(report!$B$75,data!$E:$E,0)),-6,(report!$H$75-5)-(report!$B$77-1),2,report!$B$77)
Name G16_Data: OFFSET(INDEX(data!$E:$E,MATCH(report!$B$80,data!$E:$E,0)),-1,(report!$H$80-5)-(report!$B$82-1),1,report!$B$82)
Name G16_Lie: OFFSET(INDEX(data!$E:$E,MATCH(report!$B$80,data!$E:$E,0)),-3,(report!$H$80-5)-(report!$B$82-1),1,report!$B$82)
Name G16_Lse: OFFSET(INDEX(data!$E:$E,MATCH(report!$B$80,data!$E:$E,0)),-2,(report!$H$80-5)-(report!$B$82-1),1,report!$B$82)
Name G16_Nominal: OFFSET(INDEX(data!$E:$E,MATCH(report!$B$80,data!$E:$E,0)),-4,(report!$H$80-5)-(report!$B$82-1),1,report!$B$82)
Name G16_XValues: OFFSET(INDEX(data!$E:$E,MATCH(report!$B$80,data!$E:$E,0)),-6,(report!$H$80-5)-(report!$B$82-1),2,report!$B$82)
Name G17_Data: OFFSET(INDEX(data!$E:$E,MATCH(report!$B$85,data!$E:$E,0)),-1,(report!$H$85-5)-(report!$B$87-1),1,report!$B$87)
Name G17_Lie: OFFSET(INDEX(data!$E:$E,MATCH(report!$B$85,data!$E:$E,0)),-3,(report!$H$85-5)-(report!$B$87-1),1,report!$B$87)
Name G17_Lse: OFFSET(INDEX(data!$E:$E,MATCH(report!$B$85,data!$E:$E,0)),-2,(report!$H$85-5)-(report!$B$87-1),1,report!$B$87)
Name G17_Nominal: OFFSET(INDEX(data!$E:$E,MATCH(report!$B$85,data!$E:$E,0)),-4,(report!$H$85-5)-(report!$B$87-1),1,report!$B$87)
Name G17_XValues: OFFSET(INDEX(data!$E:$E,MATCH(report!$B$85,data!$E:$E,0)),-6,(report!$H$85-5)-(report!$B$87-1),2,report!$B$87)
Name G18_Data: OFFSET(INDEX(data!$E:$E,MATCH(report!$B$90,data!$E:$E,0)),-1,(report!$H$90-5)-(report!$B$92-1),1,report!$B$92)
Name G18_Lie: OFFSET(INDEX(data!$E:$E,MATCH(report!$B$90,data!$E:$E,0)),-3,(report!$H$90-5)-(report!$B$92-1),1,report!$B$92)
Name G18_Lse: OFFSET(INDEX(data!$E:$E,MATCH(report!$B$90,data!$E:$E,0)),-2,(report!$H$90-5)-(report!$B$92-1),1,report!$B$92)
Name G18_Nominal: OFFSET(INDEX(data!$E:$E,MATCH(report!$B$90,data!$E:$E,0)),-4,(report!$H$90-5)-(report!$B$92-1),1,report!$B$92)
Name G18_XValues: OFFSET(INDEX(data!$E:$E,MATCH(report!$B$90,data!$E:$E,0)),-6,(report!$H$90-5)-(report!$B$92-1),2,report!$B$92)
Name G19_Data: OFFSET(INDEX(data!$E:$E,MATCH(report!$B$95,data!$E:$E,0)),-1,(report!$H$95-5)-(report!$B$97-1),1,report!$B$97)
Name G19_Lie: OFFSET(INDEX(data!$E:$E,MATCH(report!$B$95,data!$E:$E,0)),-3,(report!$H$95-5)-(report!$B$97-1),1,report!$B$97)
Name G19_Lse: OFFSET(INDEX(data!$E:$E,MATCH(report!$B$95,data!$E:$E,0)),-2,(report!$H$95-5)-(report!$B$97-1),1,report!$B$97)
Name G19_Nominal: OFFSET(INDEX(data!$E:$E,MATCH(report!$B$95,data!$E:$E,0)),-4,(report!$H$95-5)-(report!$B$97-1),1,report!$B$97)
Name G19_XValues: OFFSET(INDEX(data!$E:$E,MATCH(report!$B$95,data!$E:$E,0)),-6,(report!$H$95-5)-(report!$B$97-1),2,report!$B$97)
Name G2_Data: OFFSET(INDEX(data!$E:$E,MATCH(report!$B$10,data!$E:$E,0)),-1,(report!$H$10-5)-(report!$B$12-1),1,report!$B$12)
Name G2_Lie: OFFSET(INDEX(data!$E:$E,MATCH(report!$B$10,data!$E:$E,0)),-3,(report!$H$10-5)-(report!$B$12-1),1,report!$B$12)
Name G2_Lse: OFFSET(INDEX(data!$E:$E,MATCH(report!$B$10,data!$E:$E,0)),-2,(report!$H$10-5)-(report!$B$12-1),1,report!$B$12)
Name G2_Nominal: OFFSET(INDEX(data!$E:$E,MATCH(report!$B$10,data!$E:$E,0)),-4,(report!$H$10-5)-(report!$B$12-1),1,report!$B$12)
Name G2_XValues: OFFSET(INDEX(data!$E:$E,MATCH(report!$B$10,data!$E:$E,0)),-6,(report!$H$10-5)-(report!$B$12-1),2,report!$B$12)

Sheet report
A1: =data!B8 -> Part Model N - Cep Report
A3: Date: | B3: =data!A1 -> 15/06/2026 | D3: Time: | E3: =data!B1 -> 0.50347222 | H3: ="Nº of Features: "&(COUNTA(data!A:A)-1)/7 -> Nº of Features: 20
A4: Report image | J4: Group ID | K4: Group Description | L4: Feature Id | M4: Axis | N4: Deviation | O4: Cp | P4: Cpk
A5: Id: | B5: PART01_01L_X | C5: Description: | D5: =OFFSET(INDEX(data!E:E,MATCH(B5,data!E:E,0)),0,1) -> Upper Part Inboard LH Hole - Pos X | H5: =OFFSET(INDEX(data!E:E,MATCH(B5,data!E:E,0)),0,3) -> 62 | J5: =OFFSET(INDEX(data!E:E,MATCH(B5,data!E:E,0)),0,-2) -> PART01 | K5: =OFFSET(INDEX(data!E:E,MATCH(B5,data!E:E,0)),0,-1) -> Upper Sub-Assembly | L5: =B5 -> PART01_01L_X | M5: =B6 -> Pos X | N5: =F7 -> 0.76532258 | O5: =F8 -> 2.1561263 | P5: =F9 -> 1.6060823
A6: Axis: | B6: =OFFSET(INDEX(data!E:E,MATCH(B5,data!E:E,0)),0,2) -> Pos X | C6: Nominal: | D6: =OFFSET(INDEX(data!E:E,MATCH(B5,data!E:E,0)),-4,(H5-5)-(B7-1)) -> 226.2 | E6: Average: | F6: =AVERAGE(OFFSET(INDEX(data!E:E,MATCH(B5,data!E:E,0)),-1,(H5-5)-(B7-1),1,B7)) -> 226.96532 | J6: =J5 -> PART01 | K6: =K5 -> Upper Sub-Assembly | L6: =L5 -> PART01_01L_X | M6: =M5 -> Pos X | N6: =N5 -> 0.76532258 | O6: =O5 -> 2.1561263 | P6: =P5 -> 1.6060823
A7: N: | B7: =H5 -> 62 | C7: LIE: | D7: =OFFSET(INDEX(data!E:E,MATCH(B5,data!E:E,0)),-3,(H5-5)-(B7-1)) -> 223.2 | E7: Deviation: | F7: =F6-D6 -> 0.76532258 | J7: =J6 -> PART01 | K7: =K6 -> Upper Sub-Assembly | L7: =L6 -> PART01_01L_X | M7: =M6 -> Pos X | N7: =N6 -> 0.76532258 | O7: =O6 -> 2.1561263 | P7: =P6 -> 1.6060823
A8: From: | B8: =OFFSET(INDEX(data!E:E,MATCH(B5,data!E:E,0)),-6,(H5-5)-(B7-1)) -> 46169 | C8: LSE: | D8: =OFFSET(INDEX(data!E:E,MATCH(B5,data!E:E,0)),-2,(H5-5)-(B7-1)) -> 229.2 | E8: Cp: | F8: =(D8-D7)/(6*_xlfn.STDEV.P(OFFSET(INDEX(data!E:E,MATCH(B5,data!E:E,0)),-1,(H5-5)-(B7-1),1,B7))) -> 2.1561263 | J8: =J7 -> PART01 | K8: =K7 -> Upper Sub-Assembly | L8: =L7 -> PART01_01L_X | M8: =M7 -> Pos X | N8: =N7 -> 0.76532258 | O8: =O7 -> 2.1561263 | P8: =P7 -> 1.6060823
A9: To: | B9: =OFFSET(INDEX(data!E:E,MATCH(B5,data!E:E,0)),-6,H5-5) -> 46186 | C9: Last value: | D9: =OFFSET(INDEX(data!E:E,MATCH(B5,data!E:E,0)),-1,H5-5) -> 227 | E9: Cpk: | F9: =MIN((D8-F6)/(3*_xlfn.STDEV.P(OFFSET(INDEX(data!E:E,MATCH(B5,data!E:E,0)),-1,(H5-5)-(B7-1),1,B7))),(F6-D7)/(3*_xlfn.STDEV.P(OFFSET(INDEX(data!E:E,MATCH(B5,data!E:E,0)),-1,(H5-5)-(B7-1),1,B7)))) -> 1.6060823 | J9: =J8 -> PART01 | K9: =K8 -> Upper Sub-Assembly | L9: =L8 -> PART01_01L_X | M9: =M8 -> Pos X | N9: =N8 -> 0.76532258 | O9: =O8 -> 2.1561263 | P9: =P8 -> 1.6060823
A10: Id: | B10: PART01_01L_Y | C10: Description: | D10: =OFFSET(INDEX(data!E:E,MATCH(B10,data!E:E,0)),0,1) -> Upper Part Inboard LH Hole - Pos Y | H10: =OFFSET(INDEX(data!E:E,MATCH(B10,data!E:E,0)),0,3) -> 62 | J10: =OFFSET(INDEX(data!E:E,MATCH(B10,data!E:E,0)),0,-2) -> PART01 | K10: =OFFSET(INDEX(data!E:E,MATCH(B10,data!E:E,0)),0,-1) -> Upper Sub-Assembly | L10: =B10 -> PART01_01L_Y | M10: =B11 -> Pos Y | N10: =F12 -> -1.7030645 | O10: =F13 -> 1.6053393 | P10: =F14 -> 0.69400715
A11: Axis: | B11: =OFFSET(INDEX(data!E:E,MATCH(B10,data!E:E,0)),0,2) -> Pos Y | C11: Nominal: | D11: =OFFSET(INDEX(data!E:E,MATCH(B10,data!E:E,0)),-4,(H10-5)-(B12-1)) -> -326 | E11: Average: | F11: =AVERAGE(OFFSET(INDEX(data!E:E,MATCH(B10,data!E:E,0)),-1,(H10-5)-(B12-1),1,B12)) -> -327.70306 | J11: =J10 -> PART01 | K11: =K10 -> Upper Sub-Assembly | L11: =L10 -> PART01_01L_Y | M11: =M10 -> Pos Y | N11: =N10 -> -1.7030645 | O11: =O10 -> 1.6053393 | P11: =P10 -> 0.69400715
A12: N: | B12: =H10 -> 62 | C12: LIE: | D12: =OFFSET(INDEX(data!E:E,MATCH(B10,data!E:E,0)),-3,(H10-5)-(B12-1)) -> -329 | E12: Deviation: | F12: =F11-D11 -> -1.7030645 | J12: =J11 -> PART01 | K12: =K11 -> Upper Sub-Assembly | L12: =L11 -> PART01_01L_Y | M12: =M11 -> Pos Y | N12: =N11 -> -1.7030645 | O12: =O11 -> 1.6053393 | P12: =P11 -> 0.69400715
A13: From: | B13: =OFFSET(INDEX(data!E:E,MATCH(B10,data!E:E,0)),-6,(H10-5)-(B12-1)) -> 46169 | C13: LSE: | D13: =OFFSET(INDEX(data!E:E,MATCH(B10,data!E:E,0)),-2,(H10-5)-(B12-1)) -> -323 | E13: Cp: | F13: =(D13-D12)/(6*_xlfn.STDEV.P(OFFSET(INDEX(data!E:E,MATCH(B10,data!E:E,0)),-1,(H10-5)-(B12-1),1,B12))) -> 1.6053393 | J13: =J12 -> PART01 | K13: =K12 -> Upper Sub-Assembly | L13: =L12 -> PART01_01L_Y | M13: =M12 -> Pos Y | N13: =N12 -> -1.7030645 | O13: =O12 -> 1.6053393 | P13: =P12 -> 0.69400715
A14: To: | B14: =OFFSET(INDEX(data!E:E,MATCH(B10,data!E:E,0)),-6,H10-5) -> 46186 | C14: Last value: | D14: =OFFSET(INDEX(data!E:E,MATCH(B10,data!E:E,0)),-1,H10-5) -> -327.89 | E14: Cpk: | F14: =MIN((D13-F11)/(3*_xlfn.STDEV.P(OFFSET(INDEX(data!E:E,MATCH(B10,data!E:E,0)),-1,(H10-5)-(B12-1),1,B12))),(F11-D12)/(3*_xlfn.STDEV.P(OFFSET(INDEX(data!E:E,MATCH(B10,data!E:E,0)),-1,(H10-5)-(B12-1),1,B12)))) -> 0.69400715 | J14: =J13 -> PART01 | K14: =K13 -> Upper Sub-Assembly | L14: =L13 -> PART01_01L_Y | M14: =M13 -> Pos Y | N14: =N13 -> -1.7030645 | O14: =O13 -> 1.6053393 | P14: =P13 -> 0.69400715
A15: Id: | B15: PART01_01L_Z | C15: Description: | D15: =OFFSET(INDEX(data!E:E,MATCH(B15,data!E:E,0)),0,1) -> Upper Part Inboard LH Hole - Pos Z | H15: =OFFSET(INDEX(data!E:E,MATCH(B15,data!E:E,0)),0,3) -> 62 | J15: =OFFSET(INDEX(data!E:E,MATCH(B15,data!E:E,0)),0,-2) -> PART01 | K15: =OFFSET(INDEX(data!E:E,MATCH(B15,data!E:E,0)),0,-1) -> Upper Sub-Assembly | L15: =B15 -> PART01_01L_Z | M15: =B16 -> Pos Z | N15: =F17 -> -0.43935484 | O15: =F18 -> 2.8341792 | P15: =F19 -> 2.4191091
A16: Axis: | B16: =OFFSET(INDEX(data!E:E,MATCH(B15,data!E:E,0)),0,2) -> Pos Z | C16: Nominal: | D16: =OFFSET(INDEX(data!E:E,MATCH(B15,data!E:E,0)),-4,(H15-5)-(B17-1)) -> 990.2 | E16: Average: | F16: =AVERAGE(OFFSET(INDEX(data!E:E,MATCH(B15,data!E:E,0)),-1,(H15-5)-(B17-1),1,B17)) -> 989.76065 | J16: =J15 -> PART01 | K16: =K15 -> Upper Sub-Assembly | L16: =L15 -> PART01_01L_Z | M16: =M15 -> Pos Z | N16: =N15 -> -0.43935484 | O16: =O15 -> 2.8341792 | P16: =P15 -> 2.4191091
A17: N: | B17: =H15 -> 62 | C17: LIE: | D17: =OFFSET(INDEX(data!E:E,MATCH(B15,data!E:E,0)),-3,(H15-5)-(B17-1)) -> 987.2 | E17: Deviation: | F17: =F16-D16 -> -0.43935484 | J17: =J16 -> PART01 | K17: =K16 -> Upper Sub-Assembly | L17: =L16 -> PART01_01L_Z | M17: =M16 -> Pos Z | N17: =N16 -> -0.43935484 | O17: =O16 -> 2.8341792 | P17: =P16 -> 2.4191091
A18: From: | B18: =OFFSET(INDEX(data!E:E,MATCH(B15,data!E:E,0)),-6,(H15-5)-(B17-1)) -> 46169 | C18: LSE: | D18: =OFFSET(INDEX(data!E:E,MATCH(B15,data!E:E,0)),-2,(H15-5)-(B17-1)) -> 993.2 | E18: Cp: | F18: =(D18-D17)/(6*_xlfn.STDEV.P(OFFSET(INDEX(data!E:E,MATCH(B15,data!E:E,0)),-1,(H15-5)-(B17-1),1,B17))) -> 2.8341792 | J18: =J17 -> PART01 | K18: =K17 -> Upper Sub-Assembly | L18: =L17 -> PART01_01L_Z | M18: =M17 -> Pos Z | N18: =N17 -> -0.43935484 | O18: =O17 -> 2.8341792 | P18: =P17 -> 2.4191091
A19: To: | B19: =OFFSET(INDEX(data!E:E,MATCH(B15,data!E:E,0)),-6,H15-5) -> 46186 | C19: Last value: | D19: =OFFSET(INDEX(data!E:E,MATCH(B15,data!E:E,0)),-1,H15-5) -> 989.09 | E19: Cpk: | F19: =MIN((D18-F16)/(3*_xlfn.STDEV.P(OFFSET(INDEX(data!E:E,MATCH(B15,data!E:E,0)),-1,(H15-5)-(B17-1),1,B17))),(F16-D17)/(3*_xlfn.STDEV.P(OFFSET(INDEX(data!E:E,MATCH(B15,data!E:E,0)),-1,(H15-5)-(B17-1),1,B17)))) -> 2.4191091 | J19: =J18 -> PART01 | K19: =K18 -> Upper Sub-Assembly | L19: =L18 -> PART01_01L_Z | M19: =M18 -> Pos Z | N19: =N18 -> -0.43935484 | O19: =O18 -> 2.8341792 | P19: =P18 -> 2.4191091
A20: Id: | B20: PART01_01R_X | C20: Description: | D20: =OFFSET(INDEX(data!E:E,MATCH(B20,data!E:E,0)),0,1) -> Upper Part Inboard RH Hole - Pos X | H20: =OFFSET(INDEX(data!E:E,MATCH(B20,data!E:E,0)),0,3) -> 62 | J20: =OFFSET(INDEX(data!E:E,MATCH(B20,data!E:E,0)),0,-2) -> PART01 | K20: =OFFSET(INDEX(data!E:E,MATCH(B20,data!E:E,0)),0,-1) -> Upper Sub-Assembly | L20: =B20 -> PART01_01R_X | M20: =B21 -> Pos X | N20: =F22 -> 0.69774194 | O20: =F23 -> 1.7252764 | P20: =F24 -> 1.3240105
A21: Axis: | B21: =OFFSET(INDEX(data!E:E,MATCH(B20,data!E:E,0)),0,2) -> Pos X | C21: Nominal: | D21: =OFFSET(INDEX(data!E:E,MATCH(B20,data!E:E,0)),-4,(H20-5)-(B22-1)) -> 226.2 | E21: Average: | F21: =AVERAGE(OFFSET(INDEX(data!E:E,MATCH(B20,data!E:E,0)),-1,(H20-5)-(B22-1),1,B22)) -> 226.89774 | J21: =J20 -> PART01 | K21: =K20 -> Upper Sub-Assembly | L21: =L20 -> PART01_01R_X | M21: =M20 -> Pos X | N21: =N20 -> 0.69774194 | O21: =O20 -> 1.7252764 | P21: =P20 -> 1.3240105
A22: N: | B22: =H20 -> 62 | C22: LIE: | D22: =OFFSET(INDEX(data!E:E,MATCH(B20,data!E:E,0)),-3,(H20-5)-(B22-1)) -> 223.2 | E22: Deviation: | F22: =F21-D21 -> 0.69774194 | J22: =J21 -> PART01 | K22: =K21 -> Upper Sub-Assembly | L22: =L21 -> PART01_01R_X | M22: =M21 -> Pos X | N22: =N21 -> 0.69774194 | O22: =O21 -> 1.7252764 | P22: =P21 -> 1.3240105
A23: From: | B23: =OFFSET(INDEX(data!E:E,MATCH(B20,data!E:E,0)),-6,(H20-5)-(B22-1)) -> 46169 | C23: LSE: | D23: =OFFSET(INDEX(data!E:E,MATCH(B20,data!E:E,0)),-2,(H20-5)-(B22-1)) -> 229.2 | E23: Cp: | F23: =(D23-D22)/(6*_xlfn.STDEV.P(OFFSET(INDEX(data!E:E,MATCH(B20,data!E:E,0)),-1,(H20-5)-(B22-1),1,B22))) -> 1.7252764 | J23: =J22 -> PART01 | K23: =K22 -> Upper Sub-Assembly | L23: =L22 -> PART01_01R_X | M23: =M22 -> Pos X | N23: =N22 -> 0.69774194 | O23: =O22 -> 1.7252764 | P23: =P22 -> 1.3240105
A24: To: | B24: =OFFSET(INDEX(data!E:E,MATCH(B20,data!E:E,0)),-6,H20-5) -> 46186 | C24: Last value: | D24: =OFFSET(INDEX(data!E:E,MATCH(B20,data!E:E,0)),-1,H20-5) -> 226.98 | E24: Cpk: | F24: =MIN((D23-F21)/(3*_xlfn.STDEV.P(OFFSET(INDEX(data!E:E,MATCH(B20,data!E:E,0)),-1,(H20-5)-(B22-1),1,B22))),(F21-D22)/(3*_xlfn.STDEV.P(OFFSET(INDEX(data!E:E,MATCH(B20,data!E:E,0)),-1,(H20-5)-(B22-1),1,B22)))) -> 1.3240105 | J24: =J23 -> PART01 | K24: =K23 -> Upper Sub-Assembly | L24: =L23 -> PART01_01R_X | M24: =M23 -> Pos X | N24: =N23 -> 0.69774194 | O24: =O23 -> 1.7252764 | P24: =P23 -> 1.3240105
A25: Id: | B25: PART01_01R_Y | C25: Description: | D25: =OFFSET(INDEX(data!E:E,MATCH(B25,data!E:E,0)),0,1) -> Upper Part Inboard RH Hole - Pos Y | H25: =OFFSET(INDEX(data!E:E,MATCH(B25,data!E:E,0)),0,3) -> 62 | J25: =OFFSET(INDEX(data!E:E,MATCH(B25,data!E:E,0)),0,-2) -> PART01 | K25: =OFFSET(INDEX(data!E:E,MATCH(B25,data!E:E,0)),0,-1) -> Upper Sub-Assembly | L25: =B25 -> PART01_01R_Y | M25: =B26 -> Pos Y | N25: =F27 -> 1.4803226 | O25: =F28 -> 1.4359881 | P25: =F29 -> 0.7274129
A26: Axis: | B26: =OFFSET(INDEX(data!E:E,MATCH(B25,data!E:E,0)),0,2) -> Pos Y | C26: Nominal: | D26: =OFFSET(INDEX(data!E:E,MATCH(B25,data!E:E,0)),-4,(H25-5)-(B27-1)) -> 326 | E26: Average: | F26: =AVERAGE(OFFSET(INDEX(data!E:E,MATCH(B25,data!E:E,0)),-1,(H25-5)-(B27-1),1,B27)) -> 327.48032 | J26: =J25 -> PART01 | K26: =K25 -> Upper Sub-Assembly | L26: =L25 -> PART01_01R_Y | M26: =M25 -> Pos Y | N26: =N25 -> 1.4803226 | O26: =O25 -> 1.4359881 | P26: =P25 -> 0.7274129
A27: N: | B27: =H25 -> 62 | C27: LIE: | D27: =OFFSET(INDEX(data!E:E,MATCH(B25,data!E:E,0)),-3,(H25-5)-(B27-1)) -> 323 | E27: Deviation: | F27: =F26-D26 -> 1.4803226 | J27: =J26 -> PART01 | K27: =K26 -> Upper Sub-Assembly | L27: =L26 -> PART01_01R_Y | M27: =M26 -> Pos Y | N27: =N26 -> 1.4803226 | O27: =O26 -> 1.4359881 | P27: =P26 -> 0.7274129
A28: From: | B28: =OFFSET(INDEX(data!E:E,MATCH(B25,data!E:E,0)),-6,(H25-5)-(B27-1)) -> 46169 | C28: LSE: | D28: =OFFSET(INDEX(data!E:E,MATCH(B25,data!E:E,0)),-2,(H25-5)-(B27-1)) -> 329 | E28: Cp: | F28: =(D28-D27)/(6*_xlfn.STDEV.P(OFFSET(INDEX(data!E:E,MATCH(B25,data!E:E,0)),-1,(H25-5)-(B27-1),1,B27))) -> 1.4359881 | J28: =J27 -> PART01 | K28: =K27 -> Upper Sub-Assembly | L28: =L27 -> PART01_01R_Y | M28: =M27 -> Pos Y | N28: =N27 -> 1.4803226 | O28: =O27 -> 1.4359881 | P28: =P27 -> 0.7274129
A29: To: | B29: =OFFSET(INDEX(data!E:E,MATCH(B25,data!E:E,0)),-6,H25-5) -> 46186 | C29: Last value: | D29: =OFFSET(INDEX(data!E:E,MATCH(B25,data!E:E,0)),-1,H25-5) -> 326.93 | E29: Cpk: | F29: =MIN((D28-F26)/(3*_xlfn.STDEV.P(OFFSET(INDEX(data!E:E,MATCH(B25,data!E:E,0)),-1,(H25-5)-(B27-1),1,B27))),(F26-D27)/(3*_xlfn.STDEV.P(OFFSET(INDEX(data!E:E,MATCH(B25,data!E:E,0)),-1,(H25-5)-(B27-1),1,B27)))) -> 0.7274129 | J29: =J28 -> PART01 | K29: =K28 -> Upper Sub-Assembly | L29: =L28 -> PART01_01R_Y | M29: =M28 -> Pos Y | N29: =N28 -> 1.4803226 | O29: =O28 -> 1.4359881 | P29: =P28 -> 0.7274129
A30: Id: | B30: PART01_01R_Z | C30: Description: | D30: =OFFSET(INDEX(data!E:E,MATCH(B30,data!E:E,0)),0,1) -> Upper Part Inboard RH Hole - Pos Z | H30: =OFFSET(INDEX(data!E:E,MATCH(B30,data!E:E,0)),0,3) -> 62 | J30: =OFFSET(INDEX(data!E:E,MATCH(B30,data!E:E,0)),0,-2) -> PART01 | K30: =OFFSET(INDEX(data!E:E,MATCH(B30,data!E:E,0)),0,-1) -> Upper Sub-Assembly | L30: =B30 -> PART01_01R_Z | M30: =B31 -> Pos Z | N30: =F32 -> -0.96548387 | O30: =F33 -> 2.889834 | P30: =F34 -> 1.9598046
A31: Axis: | B31: =OFFSET(INDEX(data!E:E,MATCH(B30,data!E:E,0)),0,2) -> Pos Z | C31: Nominal: | D31: =OFFSET(INDEX(data!E:E,MATCH(B30,data!E:E,0)),-4,(H30-5)-(B32-1)) -> 990.2 | E31: Average: | F31: =AVERAGE(OFFSET(INDEX(data!E:E,MATCH(B30,data!E:E,0)),-1,(H30-5)-(B32-1),1,B32)) -> 989.23452 | J31: =J30 -> PART01 | K31: =K30 -> Upper Sub-Assembly | L31: =L30 -> PART01_01R_Z | M31: =M30 -> Pos Z | N31: =N30 -> -0.96548387 | O31: =O30 -> 2.889834 | P31: =P30 -> 1.9598046
A32: N: | B32: =H30 -> 62 | C32: LIE: | D32: =OFFSET(INDEX(data!E:E,MATCH(B30,data!E:E,0)),-3,(H30-5)-(B32-1)) -> 987.2 | E32: Deviation: | F32: =F31-D31 -> -0.96548387 | J32: =J31 -> PART01 | K32: =K31 -> Upper Sub-Assembly | L32: =L31 -> PART01_01R_Z | M32: =M31 -> Pos Z | N32: =N31 -> -0.96548387 | O32: =O31 -> 2.889834 | P32: =P31 -> 1.9598046
A33: From: | B33: =OFFSET(INDEX(data!E:E,MATCH(B30,data!E:E,0)),-6,(H30-5)-(B32-1)) -> 46169 | C33: LSE: | D33: =OFFSET(INDEX(data!E:E,MATCH(B30,data!E:E,0)),-2,(H30-5)-(B32-1)) -> 993.2 | E33: Cp: | F33: =(D33-D32)/(6*_xlfn.STDEV.P(OFFSET(INDEX(data!E:E,MATCH(B30,data!E:E,0)),-1,(H30-5)-(B32-1),1,B32))) -> 2.889834 | J33: =J32 -> PART01 | K33: =K32 -> Upper Sub-Assembly | L33: =L32 -> PART01_01R_Z | M33: =M32 -> Pos Z | N33: =N32 -> -0.96548387 | O33: =O32 -> 2.889834 | P33: =P32 -> 1.9598046
A34: To: | B34: =OFFSET(INDEX(data!E:E,MATCH(B30,data!E:E,0)),-6,H30-5) -> 46186 | C34: Last value: | D34: =OFFSET(INDEX(data!E:E,MATCH(B30,data!E:E,0)),-1,H30-5) -> 988.68 | E34: Cpk: | F34: =MIN((D33-F31)/(3*_xlfn.STDEV.P(OFFSET(INDEX(data!E:E,MATCH(B30,data!E:E,0)),-1,(H30-5)-(B32-1),1,B32))),(F31-D32)/(3*_xlfn.STDEV.P(OFFSET(INDEX(data!E:E,MATCH(B30,data!E:E,0)),-1,(H30-5)-(B32-1),1,B32)))) -> 1.9598046 | J34: =J33 -> PART01 | K34: =K33 -> Upper Sub-Assembly | L34: =L33 -> PART01_01R_Z | M34: =M33 -> Pos Z | N34: =N33 -> -0.96548387 | O34: =O33 -> 2.889834 | P34: =P33 -> 1.9598046
A35: Id: | B35: PART01_02R_X | C35: Description: | D35: =OFFSET(INDEX(data!E:E,MATCH(B35,data!E:E,0)),0,1) -> Upper Part Outboard RH Hole - Pos X | H35: =OFFSET(INDEX(data!E:E,MATCH(B35,data!E:E,0)),0,3) -> 62 | J35: =OFFSET(INDEX(data!E:E,MATCH(B35,data!E:E,0)),0,-2) -> PART01 | K35: =OFFSET(INDEX(data!E:E,MATCH(B35,data!E:E,0)),0,-1) -> Upper Sub-Assembly | L35: =B35 -> PART01_02R_X | M35: =B36 -> Pos X | N35: =F37 -> 1.5417742 | O35: =F38 -> 1.6963659 | P35: =F39 -> 0.82456149
A36: Axis: | B36: =OFFSET(INDEX(data!E:E,MATCH(B35,data!E:E,0)),0,2) -> Pos X | C36: Nominal: | D36: =OFFSET(INDEX(data!E:E,MATCH(B35,data!E:E,0)),-4,(H35-5)-(B37-1)) -> 226.2 | E36: Average: | F36: =AVERAGE(OFFSET(INDEX(data!E:E,MATCH(B35,data!E:E,0)),-1,(H35-5)-(B37-1),1,B37)) -> 227.74177 | J36: =J35 -> PART01 | K36: =K35 -> Upper Sub-Assembly | L36: =L35 -> PART01_02R_X | M36: =M35 -> Pos X | N36: =N35 -> 1.5417742 | O36: =O35 -> 1.6963659 | P36: =P35 -> 0.82456149
A37: N: | B37: =H35 -> 62 | C37: LIE: | D37: =OFFSET(INDEX(data!E:E,MATCH(B35,data!E:E,0)),-3,(H35-5)-(B37-1)) -> 223.2 | E37: Deviation: | F37: =F36-D36 -> 1.5417742 | J37: =J36 -> PART01 | K37: =K36 -> Upper Sub-Assembly | L37: =L36 -> PART01_02R_X | M37: =M36 -> Pos X | N37: =N36 -> 1.5417742 | O37: =O36 -> 1.6963659 | P37: =P36 -> 0.82456149
A38: From: | B38: =OFFSET(INDEX(data!E:E,MATCH(B35,data!E:E,0)),-6,(H35-5)-(B37-1)) -> 46169 | C38: LSE: | D38: =OFFSET(INDEX(data!E:E,MATCH(B35,data!E:E,0)),-2,(H35-5)-(B37-1)) -> 229.2 | E38: Cp: | F38: =(D38-D37)/(6*_xlfn.STDEV.P(OFFSET(INDEX(data!E:E,MATCH(B35,data!E:E,0)),-1,(H35-5)-(B37-1),1,B37))) -> 1.6963659 | J38: =J37 -> PART01 | K38: =K37 -> Upper Sub-Assembly | L38: =L37 -> PART01_02R_X | M38: =M37 -> Pos X | N38: =N37 -> 1.5417742 | O38: =O37 -> 1.6963659 | P38: =P37 -> 0.82456149
A39: To: | B39: =OFFSET(INDEX(data!E:E,MATCH(B35,data!E:E,0)),-6,H35-5) -> 46186 | C39: Last value: | D39: =OFFSET(INDEX(data!E:E,MATCH(B35,data!E:E,0)),-1,H35-5) -> 227.77 | E39: Cpk: | F39: =MIN((D38-F36)/(3*_xlfn.STDEV.P(OFFSET(INDEX(data!E:E,MATCH(B35,data!E:E,0)),-1,(H35-5)-(B37-1),1,B37))),(F36-D37)/(3*_xlfn.STDEV.P(OFFSET(INDEX(data!E:E,MATCH(B35,data!E:E,0)),-1,(H35-5)-(B37-1),1,B37)))) -> 0.82456149 | J39: =J38 -> PART01 | K39: =K38 -> Upper Sub-Assembly | L39: =L38 -> PART01_02R_X | M39: =M38 -> Pos X | N39: =N38 -> 1.5417742 | O39: =O38 -> 1.6963659 | P39: =P38 -> 0.82456149
A40: Id: | B40: PART01_02R_Y | C40: Description: | D40: =OFFSET(INDEX(data!E:E,MATCH(B40,data!E:E,0)),0,1) -> Upper Part Outboard RH Hole - Pos Y | H40: =OFFSET(INDEX(data!E:E,MATCH(B40,data!E:E,0)),0,3) -> 62 | J40: =OFFSET(INDEX(data!E:E,MATCH(B40,data!E:E,0)),0,-2) -> PART01 | K40: =OFFSET(INDEX(data!E:E,MATCH(B40,data!E:E,0)),0,-1) -> Upper Sub-Assembly | L40: =B40 -> PART01_02R_Y | M40: =B41 -> Pos Y | N40: =F42 -> 0.68774194 | O40: =F43 -> 1.3692067 | P40: =F44 -> 1.0553197
A41: Axis: | B41: =OFFSET(INDEX(data!E:E,MATCH(B40,data!E:E,0)),0,2) -> Pos Y | C41: Nominal: | D41: =OFFSET(INDEX(data!E:E,MATCH(B40,data!E:E,0)),-4,(H40-5)-(B42-1)) -> 449 | E41: Average: | F41: =AVERAGE(OFFSET(INDEX(data!E:E,MATCH(B40,data!E:E,0)),-1,(H40-5)-(B42-1),1,B42)) -> 449.68774 | J41: =J40 -> PART01 | K41: =K40 -> Upper Sub-Assembly | L41: =L40 -> PART01_02R_Y | M41: =M40 -> Pos Y | N41: =N40 -> 0.68774194 | O41: =O40 -> 1.3692067 | P41: =P40 -> 1.0553197
...

Sheet data
A1: 15/06/2026 | B1: 0.50347222
A2: 46169 | B2: 46169 | C2: 46169 | D2: 46169 | E2: 46170 | F2: 46170 | G2: 46171 | H2: 46171 | I2: 46171 | J2: 46171 | K2: 46172 | L2: 46172 | M2: 46172 | N2: 46174 | O2: 46174 | P2: 46174 | Q2: 46174 | R2: 46175 | S2: 46175 | T2: 46175 | U2: 46176 | V2: 46176 | W2: 46176 | X2: 46176 | Y2: 46176 | Z2: 46176 | AA2: 46176 | AB2: 46177 | AC2: 46178 | AD2: 46178 | AE2: 46178 | AF2: 46179 | AG2: 46180 | AH2: 46180 | AI2: 46180 | AJ2: 46180 | AK2: 46181 | AL2: 46181 | AM2: 46181 | AN2: 46181 | AO2: 46181 | AP2: 46182 | AQ2: 46182 | AR2: 46182 | AS2: 46182 | AT2: 46182 | AU2: 46183 | AV2: 46183 | AW2: 46183 | AX2: 46183 | AY2: 46183 | AZ2: 46184 | BA2: 46184 | BB2: 46184 | BC2: 46184 | BD2: 46184 | BE2: 46185 | BF2: 46185 | BG2: 46185 | BH2: 46185 | BI2: 46186 | BJ2: 46186
A3: 816948 | B3: 816987 | C3: 816998 | D3: 817092 | E3: 817353 | F3: 817441 | G3: 817773 | H3: 817861 | I3: 817943 | J3: 817985 | K3: 818214 | L3: 818254 | M3: 818291 | N3: 818439 | O3: 818580 | P3: 818627 | Q3: 818667 | R3: 818839 | S3: 818934 | T3: 819019 | U3: 819103 | V3: 819271 | W3: 819315 | X3: 819370 | Y3: 819445 | Z3: 819491 | AA3: 819533 | AB3: 819706 | AC3: 819995 | AD3: 820041 | AE3: 820088 | AF3: 820271 | AG3: 820495 | AH3: 820568 | AI3: 820630 | AJ3: 820670 | AK3: 820873 | AL3: 820921 | AM3: 820957 | AN3: 821024 | AO3: 821060 | AP3: 821288 | AQ3: 821319 | AR3: 821356 | AS3: 821451 | AT3: 821500 | AU3: 821710 | AV3: 821754 | AW3: 821805 | AX3: 821885 | AY3: 821931 | AZ3: 822143 | BA3: 822185 | BB3: 822236 | BC3: 822306 | BD3: 822352 | BE3: 822558 | BF3: 822647 | BG3: 822737 | BH3: 822777 | BI3: 823003 | BJ3: 823082
A4: 226.2 | B4: 226.2 | C4: 226.2 | D4: 226.2 | E4: 226.2 | F4: 226.2 | G4: 226.2 | H4: 226.2 | I4: 226.2 | J4: 226.2 | K4: 226.2 | L4: 226.2 | M4: 226.2 | N4: 226.2 | O4: 226.2 | P4: 226.2 | Q4: 226.2 | R4: 226.2 | S4: 226.2 | T4: 226.2 | U4: 226.2 | V4: 226.2 | W4: 226.2 | X4: 226.2 | Y4: 226.2 | Z4: 226.2 | AA4: 226.2 | AB4: 226.2 | AC4: 226.2 | AD4: 226.2 | AE4: 226.2 | AF4: 226.2 | AG4: 226.2 | AH4: 226.2 | AI4: 226.2 | AJ4: 226.2 | AK4: 226.2 | AL4: 226.2 | AM4: 226.2 | AN4: 226.2 | AO4: 226.2 | AP4: 226.2 | AQ4: 226.2 | AR4: 226.2 | AS4: 226.2 | AT4: 226.2 | AU4: 226.2 | AV4: 226.2 | AW4: 226.2 | AX4: 226.2 | AY4: 226.2 | AZ4: 226.2 | BA4: 226.2 | BB4: 226.2 | BC4: 226.2 | BD4: 226.2 | BE4: 226.2 | BF4: 226.2 | BG4: 226.2 | BH4: 226.2 | BI4: 226.2 | BJ4: 226.2
A5: 223.2 | B5: 223.2 | C5: 223.2 | D5: 223.2 | E5: 223.2 | F5: 223.2 | G5: 223.2 | H5: 223.2 | I5: 223.2 | J5: 223.2 | K5: 223.2 | L5: 223.2 | M5: 223.2 | N5: 223.2 | O5: 223.2 | P5: 223.2 | Q5: 223.2 | R5: 223.2 | S5: 223.2 | T5: 223.2 | U5: 223.2 | V5: 223.2 | W5: 223.2 | X5: 223.2 | Y5: 223.2 | Z5: 223.2 | AA5: 223.2 | AB5: 223.2 | AC5: 223.2 | AD5: 223.2 | AE5: 223.2 | AF5: 223.2 | AG5: 223.2 | AH5: 223.2 | AI5: 223.2 | AJ5: 223.2 | AK5: 223.2 | AL5: 223.2 | AM5: 223.2 | AN5: 223.2 | AO5: 223.2 | AP5: 223.2 | AQ5: 223.2 | AR5: 223.2 | AS5: 223.2 | AT5: 223.2 | AU5: 223.2 | AV5: 223.2 | AW5: 223.2 | AX5: 223.2 | AY5: 223.2 | AZ5: 223.2 | BA5: 223.2 | BB5: 223.2 | BC5: 223.2 | BD5: 223.2 | BE5: 223.2 | BF5: 223.2 | BG5: 223.2 | BH5: 223.2 | BI5: 223.2 | BJ5: 223.2
A6: 229.2 | B6: 229.2 | C6: 229.2 | D6: 229.2 | E6: 229.2 | F6: 229.2 | G6: 229.2 | H6: 229.2 | I6: 229.2 | J6: 229.2 | K6: 229.2 | L6: 229.2 | M6: 229.2 | N6: 229.2 | O6: 229.2 | P6: 229.2 | Q6: 229.2 | R6: 229.2 | S6: 229.2 | T6: 229.2 | U6: 229.2 | V6: 229.2 | W6: 229.2 | X6: 229.2 | Y6: 229.2 | Z6: 229.2 | AA6: 229.2 | AB6: 229.2 | AC6: 229.2 | AD6: 229.2 | AE6: 229.2 | AF6: 229.2 | AG6: 229.2 | AH6: 229.2 | AI6: 229.2 | AJ6: 229.2 | AK6: 229.2 | AL6: 229.2 | AM6: 229.2 | AN6: 229.2 | AO6: 229.2 | AP6: 229.2 | AQ6: 229.2 | AR6: 229.2 | AS6: 229.2 | AT6: 229.2 | AU6: 229.2 | AV6: 229.2 | AW6: 229.2 | AX6: 229.2 | AY6: 229.2 | AZ6: 229.2 | BA6: 229.2 | BB6: 229.2 | BC6: 229.2 | BD6: 229.2 | BE6: 229.2 | BF6: 229.2 | BG6: 229.2 | BH6: 229.2 | BI6: 229.2 | BJ6: 229.2
A7: 226.02 | B7: 227.21 | C7: 227.46 | D7: 227.7 | E7: 226.5 | F7: 227 | G7: 226.7 | H7: 226 | I7: 226.5 | J7: 227.44 | K7: 226.8 | L7: 227.06 | M7: 226.43 | N7: 227.24 | O7: 227.23 | P7: 227.47 | Q7: 226.74 | R7: 227.59 | S7: 227.7 | T7: 227.2 | U7: 226.8 | V7: 227.63 | W7: 227.2 | X7: 227.2 | Y7: 227.3 | Z7: 227.6 | AA7: 227.2 | AB7: 226.95 | AC7: 225.6 | AD7: 227.36 | AE7: 227.37 | AF7: 226.88 | AG7: 226.15 | AH7: 226.36 | AI7: 226.6 | AJ7: 226.6 | AK7: 227.38 | AL7: 227.08 | AM7: 226.53 | AN7: 226.39 | AO7: 227.43 | AP7: 226.29 | AQ7: 227.21 | AR7: 227.35 | AS7: 227.29 | AT7: 227.22 | AU7: 226.52 | AV7: 227.16 | AW7: 227.08 | AX7: 227.46 | AY7: 227.17 | AZ7: 226.42 | BA7: 227.07 | BB7: 226.99 | BC7: 227.01 | BD7: 226.75 | BE7: 226.66 | BF7: 226.84 | BG7: 226.43 | BH7: 226.71 | BI7: 227.62 | BJ7: 227
A8: PART_CEP_REP | B8: Part Model N - Cep Report | C8: PART01 | D8: Upper Sub-Assembly | E8: PART01_01L_X | F8: Upper Part Inboard LH Hole - Pos X | G8: Pos X | H8: 62
A9: 46169 | B9: 46169 | C9: 46169 | D9: 46169 | E9: 46170 | F9: 46170 | G9: 46171 | H9: 46171 | I9: 46171 | J9: 46171 | K9: 46172 | L9: 46172 | M9: 46172 | N9: 46174 | O9: 46174 | P9: 46174 | Q9: 46174 | R9: 46175 | S9: 46175 | T9: 46175 | U9: 46176 | V9: 46176 | W9: 46176 | X9: 46176 | Y9: 46176 | Z9: 46176 | AA9: 46176 | AB9: 46177 | AC9: 46178 | AD9: 46178 | AE9: 46178 | AF9: 46179 | AG9: 46180 | AH9: 46180 | AI9: 46180 | AJ9: 46180 | AK9: 46181 | AL9: 46181 | AM9: 46181 | AN9: 46181 | AO9: 46181 | AP9: 46182 | AQ9: 46182 | AR9: 46182 | AS9: 46182 | AT9: 46182 | AU9: 46183 | AV9: 46183 | AW9: 46183 | AX9: 46183 | AY9: 46183 | AZ9: 46184 | BA9: 46184 | BB9: 46184 | BC9: 46184 | BD9: 46184 | BE9: 46185 | BF9: 46185 | BG9: 46185 | BH9: 46185 | BI9: 46186 | BJ9: 46186
A10: 816948 | B10: 816987 | C10: 816998 | D10: 817092 | E10: 817353 | F10: 817441 | G10: 817773 | H10: 817861 | I10: 817943 | J10: 817985 | K10: 818214 | L10: 818254 | M10: 818291 | N10: 818439 | O10: 818580 | P10: 818627 | Q10: 818667 | R10: 818839 | S10: 818934 | T10: 819019 | U10: 819103 | V10: 819271 | W10: 819315 | X10: 819370 | Y10: 819445 | Z10: 819491 | AA10: 819533 | AB10: 819706 | AC10: 819995 | AD10: 820041 | AE10: 820088 | AF10: 820271 | AG10: 820495 | AH10: 820568 | AI10: 820630 | AJ10: 820670 | AK10: 820873 | AL10: 820921 | AM10: 820957 | AN10: 821024 | AO10: 821060 | AP10: 821288 | AQ10: 821319 | AR10: 821356 | AS10: 821451 | AT10: 821500 | AU10: 821710 | AV10: 821754 | AW10: 821805 | AX10: 821885 | AY10: 821931 | AZ10: 822143 | BA10: 822185 | BB10: 822236 | BC10: 822306 | BD10: 822352 | BE10: 822558 | BF10: 822647 | BG10: 822737 | BH10: 822777 | BI10: 823003 | BJ10: 823082
A11: -326 | B11: -326 | C11: -326 | D11: -326 | E11: -326 | F11: -326 | G11: -326 | H11: -326 | I11: -326 | J11: -326 | K11: -326 | L11: -326 | M11: -326 | N11: -326 | O11: -326 | P11: -326 | Q11: -326 | R11: -326 | S11: -326 | T11: -326 | U11: -326 | V11: -326 | W11: -326 | X11: -326 | Y11: -326 | Z11: -326 | AA11: -326 | AB11: -326 | AC11: -326 | AD11: -326 | AE11: -326 | AF11: -326 | AG11: -326 | AH11: -326 | AI11: -326 | AJ11: -326 | AK11: -326 | AL11: -326 | AM11: -326 | AN11: -326 | AO11: -326 | AP11: -326 | AQ11: -326 | AR11: -326 | AS11: -326 | AT11: -326 | AU11: -326 | AV11: -326 | AW11: -326 | AX11: -326 | AY11: -326 | AZ11: -326 | BA11: -326 | BB11: -326 | BC11: -326 | BD11: -326 | BE11: -326 | BF11: -326 | BG11: -326 | BH11: -326 | BI11: -326 | BJ11: -326
A12: -329 | B12: -329 | C12: -329 | D12: -329 | E12: -329 | F12: -329 | G12: -329 | H12: -329 | I12: -329 | J12: -329 | K12: -329 | L12: -329 | M12: -329 | N12: -329 | O12: -329 | P12: -329 | Q12: -329 | R12: -329 | S12: -329 | T12: -329 | U12: -329 | V12: -329 | W12: -329 | X12: -329 | Y12: -329 | Z12: -329 | AA12: -329 | AB12: -329 | AC12: -329 | AD12: -329 | AE12: -329 | AF12: -329 | AG12: -329 | AH12: -329 | AI12: -329 | AJ12: -329 | AK12: -329 | AL12: -329 | AM12: -329 | AN12: -329 | AO12: -329 | AP12: -329 | AQ12: -329 | AR12: -329 | AS12: -329 | AT12: -329 | AU12: -329 | AV12: -329 | AW12: -329 | AX12: -329 | AY12: -329 | AZ12: -329 | BA12: -329 | BB12: -329 | BC12: -329 | BD12: -329 | BE12: -329 | BF12: -329 | BG12: -329 | BH12: -329 | BI12: -329 | BJ12: -329
A13: -323 | B13: -323 | C13: -323 | D13: -323 | E13: -323 | F13: -323 | G13: -323 | H13: -323 | I13: -323 | J13: -323 | K13: -323 | L13: -323 | M13: -323 | N13: -323 | O13: -323 | P13: -323 | Q13: -323 | R13: -323 | S13: -323 | T13: -323 | U13: -323 | V13: -323 | W13: -323 | X13: -323 | Y13: -323 | Z13: -323 | AA13: -323 | AB13: -323 | AC13: -323 | AD13: -323 | AE13: -323 | AF13: -323 | AG13: -323 | AH13: -323 | AI13: -323 | AJ13: -323 | AK13: -323 | AL13: -323 | AM13: -323 | AN13: -323 | AO13: -323 | AP13: -323 | AQ13: -323 | AR13: -323 | AS13: -323 | AT13: -323 | AU13: -323 | AV13: -323 | AW13: -323 | AX13: -323 | AY13: -323 | AZ13: -323 | BA13: -323 | BB13: -323 | BC13: -323 | BD13: -323 | BE13: -323 | BF13: -323 | BG13: -323 | BH13: -323 | BI13: -323 | BJ13: -323
A14: -327.92 | B14: -327.13 | C14: -327.52 | D14: -326.6 | E14: -327.3 | F14: -327.5 | G14: -327 | H14: -327.9 | I14: -327.2 | J14: -327.37 | K14: -327.4 | L14: -327.59 | M14: -326.39 | N14: -327.58 | O14: -327.93 | P14: -327.49 | Q14: -328.24 | R14: -327.44 | S14: -327.7 | T14: -327.5 | U14: -329.2 | V14: -327.02 | W14: -328.2 | X14: -329 | Y14: -328.6 | Z14: -327.23 | AA14: -327.98 | AB14: -327.53 | AC14: -329.15 | AD14: -328.47 | AE14: -328.21 | AF14: -327.79 | AG14: -328.25 | AH14: -328.45 | AI14: -327 | AJ14: -328.52 | AK14: -328.44 | AL14: -326.79 | AM14: -326.79 | AN14: -326.85 | AO14: -327.08 | AP14: -327.17 | AQ14: -327.26 | AR14: -327.69 | AS14: -327.57 | AT14: -327.57 | AU14: -327.52 | AV14: -327.01 | AW14: -327.53 | AX14: -327.56 | AY14: -326.85 | AZ14: -327.99 | BA14: -327.18 | BB14: -328.16 | BC14: -327.71 | BD14: -327.96 | BE14: -328.22 | BF14: -328.45 | BG14: -328.02 | BH14: -328.84 | BI14: -328.19 | BJ14: -327.89
A15: PART_CEP_REP | B15: Part Model N - Cep Report | C15: PART01 | D15: Upper Sub-Assembly | E15: PART01_01L_Y | F15: Upper Part Inboard LH Hole - Pos Y | G15: Pos Y | H15: 62
A16: 46169 | B16: 46169 | C16: 46169 | D16: 46169 | E16: 46170 | F16: 46170 | G16: 46171 | H16: 46171 | I16: 46171 | J16: 46171 | K16: 46172 | L16: 46172 | M16: 46172 | N16: 46174 | O16: 46174 | P16: 46174 | Q16: 46174 | R16: 46175 | S16: 46175 | T16: 46175 | U16: 46176 | V16: 46176 | W16: 46176 | X16: 46176 | Y16: 46176 | Z16: 46176 | AA16: 46176 | AB16: 46177 | AC16: 46178 | AD16: 46178 | AE16: 46178 | AF16: 46179 | AG16: 46180 | AH16: 46180 | AI16: 46180 | AJ16: 46180 | AK16: 46181 | AL16: 46181 | AM16: 46181 | AN16: 46181 | AO16: 46181 | AP16: 46182 | AQ16: 46182 | AR16: 46182 | AS16: 46182 | AT16: 46182 | AU16: 46183 | AV16: 46183 | AW16: 46183 | AX16: 46183 | AY16: 46183 | AZ16: 46184 | BA16: 46184 | BB16: 46184 | BC16: 46184 | BD16: 46184 | BE16: 46185 | BF16: 46185 | BG16: 46185 | BH16: 46185 | BI16: 46186 | BJ16: 46186
A17: 816948 | B17: 816987 | C17: 816998 | D17: 817092 | E17: 817353 | F17: 817441 | G17: 817773 | H17: 817861 | I17: 817943 | J17: 817985 | K17: 818214 | L17: 818254 | M17: 818291 | N17: 818439 | O17: 818580 | P17: 818627 | Q17: 818667 | R17: 818839 | S17: 818934 | T17: 819019 | U17: 819103 | V17: 819271 | W17: 819315 | X17: 819370 | Y17: 819445 | Z17: 819491 | AA17: 819533 | AB17: 819706 | AC17: 819995 | AD17: 820041 | AE17: 820088 | AF17: 820271 | AG17: 820495 | AH17: 820568 | AI17: 820630 | AJ17: 820670 | AK17: 820873 | AL17: 820921 | AM17: 820957 | AN17: 821024 | AO17: 821060 | AP17: 821288 | AQ17: 821319 | AR17: 821356 | AS17: 821451 | AT17: 821500 | AU17: 821710 | AV17: 821754 | AW17: 821805 | AX17: 821885 | AY17: 821931 | AZ17: 822143 | BA17: 822185 | BB17: 822236 | BC17: 822306 | BD17: 822352 | BE17: 822558 | BF17: 822647 | BG17: 822737 | BH17: 822777 | BI17: 823003 | BJ17: 823082
A18: 990.2 | B18: 990.2 | C18: 990.2 | D18: 990.2 | E18: 990.2 | F18: 990.2 | G18: 990.2 | H18: 990.2 | I18: 990.2 | J18: 990.2 | K18: 990.2 | L18: 990.2 | M18: 990.2 | N18: 990.2 | O18: 990.2 | P18: 990.2 | Q18: 990.2 | R18: 990.2 | S18: 990.2 | T18: 990.2 | U18: 990.2 | V18: 990.2 | W18: 990.2 | X18: 990.2 | Y18: 990.2 | Z18: 990.2 | AA18: 990.2 | AB18: 990.2 | AC18: 990.2 | AD18: 990.2 | AE18: 990.2 | AF18: 990.2 | AG18: 990.2 | AH18: 990.2 | AI18: 990.2 | AJ18: 990.2 | AK18: 990.2 | AL18: 990.2 | AM18: 990.2 | AN18: 990.2 | AO18: 990.2 | AP18: 990.2 | AQ18: 990.2 | AR18: 990.2 | AS18: 990.2 | AT18: 990.2 | AU18: 990.2 | AV18: 990.2 | AW18: 990.2 | AX18: 990.2 | AY18: 990.2 | AZ18: 990.2 | BA18: 990.2 | BB18: 990.2 | BC18: 990.2 | BD18: 990.2 | BE18: 990.2 | BF18: 990.2 | BG18: 990.2 | BH18: 990.2 | BI18: 990.2 | BJ18: 990.2
A19: 987.2 | B19: 987.2 | C19: 987.2 | D19: 987.2 | E19: 987.2 | F19: 987.2 | G19: 987.2 | H19: 987.2 | I19: 987.2 | J19: 987.2 | K19: 987.2 | L19: 987.2 | M19: 987.2 | N19: 987.2 | O19: 987.2 | P19: 987.2 | Q19: 987.2 | R19: 987.2 | S19: 987.2 | T19: 987.2 | U19: 987.2 | V19: 987.2 | W19: 987.2 | X19: 987.2 | Y19: 987.2 | Z19: 987.2 | AA19: 987.2 | AB19: 987.2 | AC19: 987.2 | AD19: 987.2 | AE19: 987.2 | AF19: 987.2 | AG19: 987.2 | AH19: 987.2 | AI19: 987.2 | AJ19: 987.2 | AK19: 987.2 | AL19: 987.2 | AM19: 987.2 | AN19: 987.2 | AO19: 987.2 | AP19: 987.2 | AQ19: 987.2 | AR19: 987.2 | AS19: 987.2 | AT19: 987.2 | AU19: 987.2 | AV19: 987.2 | AW19: 987.2 | AX19: 987.2 | AY19: 987.2 | AZ19: 987.2 | BA19: 987.2 | BB19: 987.2 | BC19: 987.2 | BD19: 987.2 | BE19: 987.2 | BF19: 987.2 | BG19: 987.2 | BH19: 987.2 | BI19: 987.2 | BJ19: 987.2
A20: 993.2 | B20: 993.2 | C20: 993.2 | D20: 993.2 | E20: 993.2 | F20: 993.2 | G20: 993.2 | H20: 993.2 | I20: 993.2 | J20: 993.2 | K20: 993.2 | L20: 993.2 | M20: 993.2 | N20: 993.2 | O20: 993.2 | P20: 993.2 | Q20: 993.2 | R20: 993.2 | S20: 993.2 | T20: 993.2 | U20: 993.2 | V20: 993.2 | W20: 993.2 | X20: 993.2 | Y20: 993.2 | Z20: 993.2 | AA20: 993.2 | AB20: 993.2 | AC20: 993.2 | AD20: 993.2 | AE20: 993.2 | AF20: 993.2 | AG20: 993.2 | AH20: 993.2 | AI20: 993.2 | AJ20: 993.2 | AK20: 993.2 | AL20: 993.2 | AM20: 993.2 | AN20: 993.2 | AO20: 993.2 | AP20: 993.2 | AQ20: 993.2 | AR20: 993.2 | AS20: 993.2 | AT20: 993.2 | AU20: 993.2 | AV20: 993.2 | AW20: 993.2 | AX20: 993.2 | AY20: 993.2 | AZ20: 993.2 | BA20: 993.2 | BB20: 993.2 | BC20: 993.2 | BD20: 993.2 | BE20: 993.2 | BF20: 993.2 | BG20: 993.2 | BH20: 993.2 | BI20: 993.2 | BJ20: 993.2
A21: 989.14 | B21: 989.95 | C21: 989.61 | D21: 990 | E21: 989.8 | F21: 990.3 | G21: 990.2 | H21: 989.8 | I21: 989.9 | J21: 989.98 | K21: 989.87 | L21: 989.86 | M21: 990.49 | N21: 989.97 | O21: 989.71 | P21: 989.97 | Q21: 989.18 | R21: 989.75 | S21: 989.8 | T21: 989.9 | U21: 989.4 | V21: 990 | W21: 989.6 | X21: 989.8 | Y21: 990.4 | Z21: 989.97 | AA21: 990.28 | AB21: 989.57 | AC21: 989.34 | AD21: 989.67 | AE21: 990 | AF21: 989.66 | AG21: 989.47 | AH21: 989.51 | AI21: 990.2 | AJ21: 989.12 | AK21: 989.85 | AL21: 990.24 | AM21: 989.87 | AN21: 989.55 | AO21: 989.99 | AP21: 989.72 | AQ21: 990.13 | AR21: 989.8 | AS21: 989.57 | AT21: 989.9 | AU21: 989.7 | AV21: 990.12 | AW21: 989.59 | AX21: 989.53 | AY21: 990.6 | AZ21: 989.3 | BA21: 990.23 | BB21: 989.59 | BC21: 989.37 | BD21: 989.41 | BE21: 989.71 | BF21: 989.51 | BG21: 989.26 | BH21: 989.33 | BI21: 989.03 | BJ21: 989.09
A22: PART_CEP_REP | B22: Part Model N - Cep Report | C22: PART01 | D22: Upper Sub-Assembly | E22: PART01_01L_Z | F22: Upper Part Inboard LH Hole - Pos Z | G22: Pos Z | H22: 62
A23: 46169 | B23: 46169 | C23: 46169 | D23: 46169 | E23: 46170 | F23: 46170 | G23: 46171 | H23: 46171 | I23: 46171 | J23: 46171 | K23: 46172 | L23: 46172 | M23: 46172 | N23: 46174 | O23: 46174 | P23: 46174 | Q23: 46174 | R23: 46175 | S23: 46175 | T23: 46175 | U23: 46176 | V23: 46176 | W23: 46176 | X23: 46176 | Y23: 46176 | Z23: 46176 | AA23: 46176 | AB23: 46177 | AC23: 46178 | AD23: 46178 | AE23: 46178 | AF23: 46179 | AG23: 46180 | AH23: 46180 | AI23: 46180 | AJ23: 46180 | AK23: 46181 | AL23: 46181 | AM23: 46181 | AN23: 46181 | AO23: 46181 | AP23: 46182 | AQ23: 46182 | AR23: 46182 | AS23: 46182 | AT23: 46182 | AU23: 46183 | AV23: 46183 | AW23: 46183 | AX23: 46183 | AY23: 46183 | AZ23: 46184 | BA23: 46184 | BB23: 46184 | BC23: 46184 | BD23: 46184 | BE23: 46185 | BF23: 46185 | BG23: 46185 | BH23: 46185 | BI23: 46186 | BJ23: 46186
A24: 816948 | B24: 816987 | C24: 816998 | D24: 817092 | E24: 817353 | F24: 817441 | G24: 817773 | H24: 817861 | I24: 817943 | J24: 817985 | K24: 818214 | L24: 818254 | M24: 818291 | N24: 818439 | O24: 818580 | P24: 818627 | Q24: 818667 | R24: 818839 | S24: 818934 | T24: 819019 | U24: 819103 | V24: 819271 | W24: 819315 | X24: 819370 | Y24: 819445 | Z24: 819491 | AA24: 819533 | AB24: 819706 | AC24: 819995 | AD24: 820041 | AE24: 820088 | AF24: 820271 | AG24: 820495 | AH24: 820568 | AI24: 820630 | AJ24: 820670 | AK24: 820873 | AL24: 820921 | AM24: 820957 | AN24: 821024 | AO24: 821060 | AP24: 821288 | AQ24: 821319 | AR24: 821356 | AS24: 821451 | AT24: 821500 | AU24: 821710 | AV24: 821754 | AW24: 821805 | AX24: 821885 | AY24: 821931 | AZ24: 822143 | BA24: 822185 | BB24: 822236 | BC24: 822306 | BD24: 822352 | BE24: 822558 | BF24: 822647 | BG24: 822737 | BH24: 822777 | BI24: 823003 | BJ24: 823082
A25: 226.2 | B25: 226.2 | C25: 226.2 | D25: 226.2 | E25: 226.2 | F25: 226.2 | G25: 226.2 | H25: 226.2 | I25: 226.2 | J25: 226.2 | K25: 226.2 | L25: 226.2 | M25: 226.2 | N25: 226.2 | O25: 226.2 | P25: 226.2 | Q25: 226.2 | R25: 226.2 | S25: 226.2 | T25: 226.2 | U25: 226.2 | V25: 226.2 | W25: 226.2 | X25: 226.2 | Y25: 226.2 | Z25: 226.2 | AA25: 226.2 | AB25: 226.2 | AC25: 226.2 | AD25: 226.2 | AE25: 226.2 | AF25: 226.2 | AG25: 226.2 | AH25: 226.2 | AI25: 226.2 | AJ25: 226.2 | AK25: 226.2 | AL25: 226.2 | AM25: 226.2 | AN25: 226.2 | AO25: 226.2 | AP25: 226.2 | AQ25: 226.2 | AR25: 226.2 | AS25: 226.2 | AT25: 226.2 | AU25: 226.2 | AV25: 226.2 | AW25: 226.2 | AX25: 226.2 | AY25: 226.2 | AZ25: 226.2 | BA25: 226.2 | BB25: 226.2 | BC25: 226.2 | BD25: 226.2 | BE25: 226.2 | BF25: 226.2 | BG25: 226.2 | BH25: 226.2 | BI25: 226.2 | BJ25: 226.2
A26: 223.2 | B26: 223.2 | C26: 223.2 | D26: 223.2 | E26: 223.2 | F26: 223.2 | G26: 223.2 | H26: 223.2 | I26: 223.2 | J26: 223.2 | K26: 223.2 | L26: 223.2 | M26: 223.2 | N26: 223.2 | O26: 223.2 | P26: 223.2 | Q26: 223.2 | R26: 223.2 | S26: 223.2 | T26: 223.2 | U26: 223.2 | V26: 223.2 | W26: 223.2 | X26: 223.2 | Y26: 223.2 | Z26: 223.2 | AA26: 223.2 | AB26: 223.2 | AC26: 223.2 | AD26: 223.2 | AE26: 223.2 | AF26: 223.2 | AG26: 223.2 | AH26: 223.2 | AI26: 223.2 | AJ26: 223.2 | AK26: 223.2 | AL26: 223.2 | AM26: 223.2 | AN26: 223.2 | AO26: 223.2 | AP26: 223.2 | AQ26: 223.2 | AR26: 223.2 | AS26: 223.2 | AT26: 223.2 | AU26: 223.2 | AV26: 223.2 | AW26: 223.2 | AX26: 223.2 | AY26: 223.2 | AZ26: 223.2 | BA26: 223.2 | BB26: 223.2 | BC26: 223.2 | BD26: 223.2 | BE26: 223.2 | BF26: 223.2 | BG26: 223.2 | BH26: 223.2 | BI26: 223.2 | BJ26: 223.2
A27: 229.2 | B27: 229.2 | C27: 229.2 | D27: 229.2 | E27: 229.2 | F27: 229.2 | G27: 229.2 | H27: 229.2 | I27: 229.2 | J27: 229.2 | K27: 229.2 | L27: 229.2 | M27: 229.2 | N27: 229.2 | O27: 229.2 | P27: 229.2 | Q27: 229.2 | R27: 229.2 | S27: 229.2 | T27: 229.2 | U27: 229.2 | V27: 229.2 | W27: 229.2 | X27: 229.2 | Y27: 229.2 | Z27: 229.2 | AA27: 229.2 | AB27: 229.2 | AC27: 229.2 | AD27: 229.2 | AE27: 229.2 | AF27: 229.2 | AG27: 229.2 | AH27: 229.2 | AI27: 229.2 | AJ27: 229.2 | AK27: 229.2 | AL27: 229.2 | AM27: 229.2 | AN27: 229.2 | AO27: 229.2 | AP27: 229.2 | AQ27: 229.2 | AR27: 229.2 | AS27: 229.2 | AT27: 229.2 | AU27: 229.2 | AV27: 229.2 | AW27: 229.2 | AX27: 229.2 | AY27: 229.2 | AZ27: 229.2 | BA27: 229.2 | BB27: 229.2 | BC27: 229.2 | BD27: 229.2 | BE27: 229.2 | BF27: 229.2 | BG27: 229.2 | BH27: 229.2 | BI27: 229.2 | BJ27: 229.2
A28: 225.94 | B28: 226.49 | C28: 226.41 | D28: 226.7 | E28: 226.3 | F28: 227.2 | G28: 226.1 | H28: 227.8 | I28: 227.8 | J28: 227.24 | K28: 226.15 | L28: 227.81 | M28: 227.1 | N28: 226.61 | O28: 226.48 | P28: 226.9 | Q28: 226.54 | R28: 226.12 | S28: 226.7 | T28: 226.9 | U28: 227 | V28: 225.38 | W28: 227.4 | X28: 226.2 | Y28: 226.9 | Z28: 227.18 | AA28: 226.75 | AB28: 225.68 | AC28: 226.95 | AD28: 227.18 | AE28: 227.2 | AF28: 226.32 | AG28: 227.29 | AH28: 227.17 | AI28: 227.3 | AJ28: 227.84 | AK28: 226.27 | AL28: 226.44 | AM28: 226.54 | AN28: 226.75 | AO28: 226.19 | AP28: 226.74 | AQ28: 226.97 | AR28: 227.51 | AS28: 227.44 | AT28: 227.1 | AU28: 226.53 | AV28: 227.31 | AW28: 227.08 | AX28: 227.47 | AY28: 227.25 | AZ28: 227.04 | BA28: 227.77 | BB28: 226.93 | BC28: 227.93 | BD28: 227.85 | BE28: 226.42 | BF28: 227.4 | BG28: 227.75 | BH28: 227.06 | BI28: 225.91 | BJ28: 226.98
A29: PART_CEP_REP | B29: Part Model N - Cep Report | C29: PART01 | D29: Upper Sub-Assembly | E29: PART01_01R_X | F29: Upper Part Inboard RH Hole - Pos X | G29: Pos X | H29: 62
A30: 46169 | B30: 46169 | C30: 46169 | D30: 46169 | E30: 46170 | F30: 46170 | G30: 46171 | H30: 46171 | I30: 46171 | J30: 46171 | K30: 46172 | L30: 46172 | M30: 46172 | N30: 46174 | O30: 46174 | P30: 46174 | Q30: 46174 | R30: 46175 | S30: 46175 | T30: 46175 | U30: 46176 | V30: 46176 | W30: 46176 | X30: 46176 | Y30: 46176 | Z30: 46176 | AA30: 46176 | AB30: 46177 | AC30: 46178 | AD30: 46178 | AE30: 46178 | AF30: 46179 | AG30: 46180 | AH30: 46180 | AI30: 46180 | AJ30: 46180 | AK30: 46181 | AL30: 46181 | AM30: 46181 | AN30: 46181 | AO30: 46181 | AP30: 46182 | AQ30: 46182 | AR30: 46182 | AS30: 46182 | AT30: 46182 | AU30: 46183 | AV30: 46183 | AW30: 46183 | AX30: 46183 | AY30: 46183 | AZ30: 46184 | BA30: 46184 | BB30: 46184 | BC30: 46184 | BD30: 46184 | BE30: 46185 | BF30: 46185 | BG30: 46185 | BH30: 46185 | BI30: 46186 | BJ30: 46186
A31: 816948 | B31: 816987 | C31: 816998 | D31: 817092 | E31: 817353 | F31: 817441 | G31: 817773 | H31: 817861 | I31: 817943 | J31: 817985 | K31: 818214 | L31: 818254 | M31: 818291 | N31: 818439 | O31: 818580 | P31: 818627 | Q31: 818667 | R31: 818839 | S31: 818934 | T31: 819019 | U31: 819103 | V31: 819271 | W31: 819315 | X31: 819370 | Y31: 819445 | Z31: 819491 | AA31: 819533 | AB31: 819706 | AC31: 819995 | AD31: 820041 | AE31: 820088 | AF31: 820271 | AG31: 820495 | AH31: 820568 | AI31: 820630 | AJ31: 820670 | AK31: 820873 | AL31: 820921 | AM31: 820957 | AN31: 821024 | AO31: 821060 | AP31: 821288 | AQ31: 821319 | AR31: 821356 | AS31: 821451 | AT31: 821500 | AU31: 821710 | AV31: 821754 | AW31: 821805 | AX31: 821885 | AY31: 821931 | AZ31: 822143 | BA31: 822185 | BB31: 822236 | BC31: 822306 | BD31: 822352 | BE31: 822558 | BF31: 822647 | BG31: 822737 | BH31: 822777 | BI31: 823003 | BJ31: 823082
A32: 326 | B32: 326 | C32: 326 | D32: 326 | E32: 326 | F32: 326 | G32: 326 | H32: 326 | I32: 326 | J32: 326 | K32: 326 | L32: 326 | M32: 326 | N32: 326 | O32: 326 | P32: 326 | Q32: 326 | R32: 326 | S32: 326 | T32: 326 | U32: 326 | V32: 326 | W32: 326 | X32: 326 | Y32: 326 | Z32: 326 | AA32: 326 | AB32: 326 | AC32: 326 | AD32: 326 | AE32: 326 | AF32: 326 | AG32: 326 | AH32: 326 | AI32: 326 | AJ32: 326 | AK32: 326 | AL32: 326 | AM32: 326 | AN32: 326 | AO32: 326 | AP32: 326 | AQ32: 326 | AR32: 326 | AS32: 326 | AT32: 326 | AU32: 326 | AV32: 326 | AW32: 326 | AX32: 326 | AY32: 326 | AZ32: 326 | BA32: 326 | BB32: 326 | BC32: 326 | BD32: 326 | BE32: 326 | BF32: 326 | BG32: 326 | BH32: 326 | BI32: 326 | BJ32: 326
A33: 323 | B33: 323 | C33: 323 | D33: 323 | E33: 323 | F33: 323 | G33: 323 | H33: 323 | I33: 323 | J33: 323 | K33: 323 | L33: 323 | M33: 323 | N33: 323 | O33: 323 | P33: 323 | Q33: 323 | R33: 323 | S33: 323 | T33: 323 | U33: 323 | V33: 323 | W33: 323 | X33: 323 | Y33: 323 | Z33: 323 | AA33: 323 | AB33: 323 | AC33: 323 | AD33: 323 | AE33: 323 | AF33: 323 | AG33: 323 | AH33: 323 | AI33: 323 | AJ33: 323 | AK33: 323 | AL33: 323 | AM33: 323 | AN33: 323 | AO33: 323 | AP33: 323 | AQ33: 323 | AR33: 323 | AS33: 323 | AT33: 323 | AU33: 323 | AV33: 323 | AW33: 323 | AX33: 323 | AY33: 323 | AZ33: 323 | BA33: 323 | BB33: 323 | BC33: 323 | BD33: 323 | BE33: 323 | BF33: 323 | BG33: 323 | BH33: 323 | BI33: 323 | BJ33: 323
A34: 329 | B34: 329 | C34: 329 | D34: 329 | E34: 329 | F34: 329 | G34: 329 | H34: 329 | I34: 329 | J34: 329 | K34: 329 | L34: 329 | M34: 329 | N34: 329 | O34: 329 | P34: 329 | Q34: 329 | R34: 329 | S34: 329 | T34: 329 | U34: 329 | V34: 329 | W34: 329 | X34: 329 | Y34: 329 | Z34: 329 | AA34: 329 | AB34: 329 | AC34: 329 | AD34: 329 | AE34: 329 | AF34: 329 | AG34: 329 | AH34: 329 | AI34: 329 | AJ34: 329 | AK34: 329 | AL34: 329 | AM34: 329 | AN34: 329 | AO34: 329 | AP34: 329 | AQ34: 329 | AR34: 329 | AS34: 329 | AT34: 329 | AU34: 329 | AV34: 329 | AW34: 329 | AX34: 329 | AY34: 329 | AZ34: 329 | BA34: 329 | BB34: 329 | BC34: 329 | BD34: 329 | BE34: 329 | BF34: 329 | BG34: 329 | BH34: 329 | BI34: 329 | BJ34: 329
A35: 327.91 | B35: 326.58 | C35: 327.56 | D35: 327.6 | E35: 327 | F35: 326.9 | G35: 328 | H35: 327.2 | I35: 327.9 | J35: 328.87 | K35: 326.57 | L35: 326.25 | M35: 328.07 | N35: 328.25 | O35: 326.75 | P35: 326.35 | Q35: 326.44 | R35: 327.54 | S35: 327.4 | T35: 326.7 | U35: 326.3 | V35: 328.6 | W35: 326.8 | X35: 327.4 | Y35: 327.5 | Z35: 326.37 | AA35: 327.4 | AB35: 327.39 | AC35: 326.97 | AD35: 327.24 | AE35: 326.64 | AF35: 326.79 | AG35: 326.89 | AH35: 327.55 | AI35: 327.5 | AJ35: 327.39 | AK35: 327.59 | AL35: 327.29 | AM35: 327.78 | AN35: 327.86 | AO35: 327.58 | AP35: 329.54 | AQ35: 328.39 | AR35: 328.22 | AS35: 327.04 | AT35: 328.37 | AU35: 327.58 | AV35: 327.16 | AW35: 327.04 | AX35: 328.18 | AY35: 328.64 | AZ35: 328.04 | BA35: 327.6 | BB35: 326.95 | BC35: 327.53 | BD35: 327.54 | BE35: 327.31 | BF35: 327.87 | BG35: 328.01 | BH35: 328.86 | BI35: 328.31 | BJ35: 326.93
A36: PART_CEP_REP | B36: Part Model N - Cep Report | C36: PART01 | D36: Upper Sub-Assembly | E36: PART01_01R_Y | F36: Upper Part Inboard RH Hole - Pos Y | G36: Pos Y | H36: 62
A37: 46169 | B37: 46169 | C37: 46169 | D37: 46169 | E37: 46170 | F37: 46170 | G37: 46171 | H37: 46171 | I37: 46171 | J37: 46171 | K37: 46172 | L37: 46172 | M37: 46172 | N37: 46174 | O37: 46174 | P37: 46174 | Q37: 46174 | R37: 46175 | S37: 46175 | T37: 46175 | U37: 46176 | V37: 46176 | W37: 46176 | X37: 46176 | Y37: 46176 | Z37: 46176 | AA37: 46176 | AB37: 46177 | AC37: 46178 | AD37: 46178 | AE37: 46178 | AF37: 46179 | AG37: 46180 | AH37: 46180 | AI37: 46180 | AJ37: 46180 | AK37: 46181 | AL37: 46181 | AM37: 46181 | AN37: 46181 | AO37: 46181 | AP37: 46182 | AQ37: 46182 | AR37: 46182 | AS37: 46182 | AT37: 46182 | AU37: 46183 | AV37: 46183 | AW37: 46183 | AX37: 46183 | AY37: 46183 | AZ37: 46184 | BA37: 46184 | BB37: 46184 | BC37: 46184 | BD37: 46184 | BE37: 46185 | BF37: 46185 | BG37: 46185 | BH37: 46185 | BI37: 46186 | BJ37: 46186
A38: 816948 | B38: 816987 | C38: 816998 | D38: 817092 | E38: 817353 | F38: 817441 | G38: 817773 | H38: 817861 | I38: 817943 | J38: 817985 | K38: 818214 | L38: 818254 | M38: 818291 | N38: 818439 | O38: 818580 | P38: 818627 | Q38: 818667 | R38: 818839 | S38: 818934 | T38: 819019 | U38: 819103 | V38: 819271 | W38: 819315 | X38: 819370 | Y38: 819445 | Z38: 819491 | AA38: 819533 | AB38: 819706 | AC38: 819995 | AD38: 820041 | AE38: 820088 | AF38: 820271 | AG38: 820495 | AH38: 820568 | AI38: 820630 | AJ38: 820670 | AK38: 820873 | AL38: 820921 | AM38: 820957 | AN38: 821024 | AO38: 821060 | AP38: 821288 | AQ38: 821319 | AR38: 821356 | AS38: 821451 | AT38: 821500 | AU38: 821710 | AV38: 821754 | AW38: 821805 | AX38: 821885 | AY38: 821931 | AZ38: 822143 | BA38: 822185 | BB38: 822236 | BC38: 822306 | BD38: 822352 | BE38: 822558 | BF38: 822647 | BG38: 822737 | BH38: 822777 | BI38: 823003 | BJ38: 823082
A39: 990.2 | B39: 990.2 | C39: 990.2 | D39: 990.2 | E39: 990.2 | F39: 990.2 | G39: 990.2 | H39: 990.2 | I39: 990.2 | J39: 990.2 | K39: 990.2 | L39: 990.2 | M39: 990.2 | N39: 990.2 | O39: 990.2 | P39: 990.2 | Q39: 990.2 | R39: 990.2 | S39: 990.2 | T39: 990.2 | U39: 990.2 | V39: 990.2 | W39: 990.2 | X39: 990.2 | Y39: 990.2 | Z39: 990.2 | AA39: 990.2 | AB39: 990.2 | AC39: 990.2 | AD39: 990.2 | AE39: 990.2 | AF39: 990.2 | AG39: 990.2 | AH39: 990.2 | AI39: 990.2 | AJ39: 990.2 | AK39: 990.2 | AL39: 990.2 | AM39: 990.2 | AN39: 990.2 | AO39: 990.2 | AP39: 990.2 | AQ39: 990.2 | AR39: 990.2 | AS39: 990.2 | AT39: 990.2 | AU39: 990.2 | AV39: 990.2 | AW39: 990.2 | AX39: 990.2 | AY39: 990.2 | AZ39: 990.2 | BA39: 990.2 | BB39: 990.2 | BC39: 990.2 | BD39: 990.2 | BE39: 990.2 | BF39: 990.2 | BG39: 990.2 | BH39: 990.2 | BI39: 990.2 | BJ39: 990.2
A40: 987.2 | B40: 987.2 | C40: 987.2 | D40: 987.2 | E40: 987.2 | F40: 987.2 | G40: 987.2 | H40: 987.2 | I40: 987.2 | J40: 987.2 | K40: 987.2 | L40: 987.2 | M40: 987.2 | N40: 987.2 | O40: 987.2 | P40: 987.2 | Q40: 987.2 | R40: 987.2 | S40: 987.2 | T40: 987.2 | U40: 987.2 | V40: 987.2 | W40: 987.2 | X40: 987.2 | Y40: 987.2 | Z40: 987.2 | AA40: 987.2 | AB40: 987.2 | AC40: 987.2 | AD40: 987.2 | AE40: 987.2 | AF40: 987.2 | AG40: 987.2 | AH40: 987.2 | AI40: 987.2 | AJ40: 987.2 | AK40: 987.2 | AL40: 987.2 | AM40: 987.2 | AN40: 987.2 | AO40: 987.2 | AP40: 987.2 | AQ40: 987.2 | AR40: 987.2 | AS40: 987.2 | AT40: 987.2 | AU40: 987.2 | AV40: 987.2 | AW40: 987.2 | AX40: 987.2 | AY40: 987.2 | AZ40: 987.2 | BA40: 987.2 | BB40: 987.2 | BC40: 987.2 | BD40: 987.2 | BE40: 987.2 | BF40: 987.2 | BG40: 987.2 | BH40: 987.2 | BI40: 987.2 | BJ40: 987.2
...
