Workbook

Sheet report
A2: =data!B2 -> Frame Model N Report
B4: Date: | C4: =data!E2 -> 07/06/2026 | D4: Time: | E4: =data!F2 -> 17:41:35 | H4: Part Id: | I4: =data!G2 -> 51100-KKA44 | K4: Part Number: | L4: =data!H2 -> 820670
A5: Report image
B6: accuracy | C6: =(COUNTIF(Y:Y,"=TRUE*")-COUNTIF(X:X,"=TRUE")) / COUNTIF(Y:Y,"=TRUE*") -> 0.95275591 | K6: condition | L6: =IF(COUNTIF(AB:AB,"=TRUE")>0,1,0) -> 0
A8: =INDEX(data!D:D,MATCH(OFFSET(INDIRECT("RC",FALSE),3,0),data!I:I,0)) -> Front Bumper
A9: Group Image
A10: Feature Id | B10: Axis | C10: Value | D10: Nominal | E10: LIE | F10: LSE | G10: Deviation | H10: Judge | I10: OOT | J10: Description | X10: NG on Accuracy | Y10: On Accuracy | Z10: LIE (internal) | AA10: LSE (internal) | AB10: Is Rejected
A11: FA01_01R_X | B11: =VLOOKUP(A11,data!I:S,2,FALSE) -> Pos X | C11: =TRUNC(VLOOKUP(A11,data!I:S,3,FALSE),1) -> 227.8 | D11: =TRUNC(VLOOKUP(A11,data!I:S,4,FALSE),1) -> 226.2 | E11: =VLOOKUP(A11,data!I:S,5,FALSE) -> -3 | F11: =VLOOKUP(A11,data!I:S,6,FALSE) -> 3 | G11: =C11-D11 -> 1.6 | H11: =IF(OR(G11<E11,G11>F11),1,0) -> 0 | I11: =IF(H11=1,IF(G11<E11,G11-E11,G11-F11),"") | J11: =VLOOKUP(A11,data!I:S,9,FALSE) -> Inboard Nut RH - Pos X | X11: =IF(AND(H11=1,Y11="TRUE"),TRUE,"") | Y11: =VLOOKUP(A11,data!I:S,10,FALSE) -> TRUE | Z11: =VLOOKUP(A11,data!I:S,7,FALSE) -> -4.5 | AA11: =VLOOKUP(A11,data!I:S,8,FALSE) -> 4.5 | AB11: =IF(OR(G11<Z11,G11>AA11),TRUE,FALSE) -> FALSE
A12: FA01_01R_Y | B12: =VLOOKUP(A12,data!I:S,2,FALSE) -> Pos Y | C12: =TRUNC(VLOOKUP(A12,data!I:S,3,FALSE),1) -> 327.3 | D12: =TRUNC(VLOOKUP(A12,data!I:S,4,FALSE),1) -> 326 | E12: =VLOOKUP(A12,data!I:S,5,FALSE) -> -3 | F12: =VLOOKUP(A12,data!I:S,6,FALSE) -> 3 | G12: =C12-D12 -> 1.3 | H12: =IF(OR(G12<E12,G12>F12),1,0) -> 0 | I12: =IF(H12=1,IF(G12<E12,G12-E12,G12-F12),"") | J12: =VLOOKUP(A12,data!I:S,9,FALSE) -> Inboard Nut RH - Pos Y | X12: =IF(AND(H12=1,Y12="TRUE"),TRUE,"") | Y12: =VLOOKUP(A12,data!I:S,10,FALSE) -> TRUE | Z12: =VLOOKUP(A12,data!I:S,7,FALSE) -> -4.5 | AA12: =VLOOKUP(A12,data!I:S,8,FALSE) -> 4.5 | AB12: =IF(OR(G12<Z12,G12>AA12),TRUE,FALSE) -> FALSE
A13: FA01_01R_Z | B13: =VLOOKUP(A13,data!I:S,2,FALSE) -> Pos Z | C13: =TRUNC(VLOOKUP(A13,data!I:S,3,FALSE),1) -> 988.5 | D13: =TRUNC(VLOOKUP(A13,data!I:S,4,FALSE),1) -> 990.2 | E13: =VLOOKUP(A13,data!I:S,5,FALSE) -> -3 | F13: =VLOOKUP(A13,data!I:S,6,FALSE) -> 3 | G13: =C13-D13 -> -1.7 | H13: =IF(OR(G13<E13,G13>F13),1,0) -> 0 | I13: =IF(H13=1,IF(G13<E13,G13-E13,G13-F13),"") | J13: =VLOOKUP(A13,data!I:S,9,FALSE) -> Inboard Nut RH - Pos Z | X13: =IF(AND(H13=1,Y13="TRUE"),TRUE,"") | Y13: =VLOOKUP(A13,data!I:S,10,FALSE) -> TRUE | Z13: =VLOOKUP(A13,data!I:S,7,FALSE) -> -4.5 | AA13: =VLOOKUP(A13,data!I:S,8,FALSE) -> 4.5 | AB13: =IF(OR(G13<Z13,G13>AA13),TRUE,FALSE) -> FALSE
A14: FA01_02R_X | B14: =VLOOKUP(A14,data!I:S,2,FALSE) -> Pos X | C14: =TRUNC(VLOOKUP(A14,data!I:S,3,FALSE),1) -> 228.4 | D14: =TRUNC(VLOOKUP(A14,data!I:S,4,FALSE),1) -> 226.2 | E14: =VLOOKUP(A14,data!I:S,5,FALSE) -> -3 | F14: =VLOOKUP(A14,data!I:S,6,FALSE) -> 3 | G14: =C14-D14 -> 2.2 | H14: =IF(OR(G14<E14,G14>F14),1,0) -> 0 | I14: =IF(H14=1,IF(G14<E14,G14-E14,G14-F14),"") | J14: =VLOOKUP(A14,data!I:S,9,FALSE) -> Outboard Nut RH - Pos X | X14: =IF(AND(H14=1,Y14="TRUE"),TRUE,"") | Y14: =VLOOKUP(A14,data!I:S,10,FALSE) -> TRUE | Z14: =VLOOKUP(A14,data!I:S,7,FALSE) -> -4.5 | AA14: =VLOOKUP(A14,data!I:S,8,FALSE) -> 4.5 | AB14: =IF(OR(G14<Z14,G14>AA14),TRUE,FALSE) -> FALSE
A15: FA01_02R_Y | B15: =VLOOKUP(A15,data!I:S,2,FALSE) -> Pos Y | C15: =TRUNC(VLOOKUP(A15,data!I:S,3,FALSE),1) -> 449.7 | D15: =TRUNC(VLOOKUP(A15,data!I:S,4,FALSE),1) -> 449 | E15: =VLOOKUP(A15,data!I:S,5,FALSE) -> -3 | F15: =VLOOKUP(A15,data!I:S,6,FALSE) -> 3 | G15: =C15-D15 -> 0.7 | H15: =IF(OR(G15<E15,G15>F15),1,0) -> 0 | I15: =IF(H15=1,IF(G15<E15,G15-E15,G15-F15),"") | J15: =VLOOKUP(A15,data!I:S,9,FALSE) -> Outboard Nut RH - Pos Y | X15: =IF(AND(H15=1,Y15="TRUE"),TRUE,"") | Y15: =VLOOKUP(A15,data!I:S,10,FALSE) -> TRUE | Z15: =VLOOKUP(A15,data!I:S,7,FALSE) -> -4.5 | AA15: =VLOOKUP(A15,data!I:S,8,FALSE) -> 4.5 | AB15: =IF(OR(G15<Z15,G15>AA15),TRUE,FALSE) -> FALSE
A16: FA01_02R_Z | B16: =VLOOKUP(A16,data!I:S,2,FALSE) -> Pos Z | C16: =TRUNC(VLOOKUP(A16,data!I:S,3,FALSE),1) -> 1051.1 | D16: =TRUNC(VLOOKUP(A16,data!I:S,4,FALSE),1) -> 1052.3 | E16: =VLOOKUP(A16,data!I:S,5,FALSE) -> -3 | F16: =VLOOKUP(A16,data!I:S,6,FALSE) -> 3 | G16: =C16-D16 -> -1.2 | H16: =IF(OR(G16<E16,G16>F16),1,0) -> 0 | I16: =IF(H16=1,IF(G16<E16,G16-E16,G16-F16),"") | J16: =VLOOKUP(A16,data!I:S,9,FALSE) -> Outboard Nut RH - Pos Z | X16: =IF(AND(H16=1,Y16="TRUE"),TRUE,"") | Y16: =VLOOKUP(A16,data!I:S,10,FALSE) -> TRUE | Z16: =VLOOKUP(A16,data!I:S,7,FALSE) -> -4.5 | AA16: =VLOOKUP(A16,data!I:S,8,FALSE) -> 4.5 | AB16: =IF(OR(G16<Z16,G16>AA16),TRUE,FALSE) -> FALSE
A17: FA01_01L_X | B17: =VLOOKUP(A17,data!I:S,2,FALSE) -> Pos X | C17: =TRUNC(VLOOKUP(A17,data!I:S,3,FALSE),1) -> 226.6 | D17: =TRUNC(VLOOKUP(A17,data!I:S,4,FALSE),1) -> 226.2 | E17: =VLOOKUP(A17,data!I:S,5,FALSE) -> -3 | F17: =VLOOKUP(A17,data!I:S,6,FALSE) -> 3 | G17: =C17-D17 -> 0.4 | H17: =IF(OR(G17<E17,G17>F17),1,0) -> 0 | I17: =IF(H17=1,IF(G17<E17,G17-E17,G17-F17),"") | J17: =VLOOKUP(A17,data!I:S,9,FALSE) -> Inboard Nut LH - Pos X | X17: =IF(AND(H17=1,Y17="TRUE"),TRUE,"") | Y17: =VLOOKUP(A17,data!I:S,10,FALSE) -> TRUE | Z17: =VLOOKUP(A17,data!I:S,7,FALSE) -> -4.5 | AA17: =VLOOKUP(A17,data!I:S,8,FALSE) -> 4.5 | AB17: =IF(OR(G17<Z17,G17>AA17),TRUE,FALSE) -> FALSE
A18: FA01_01L_Y | B18: =VLOOKUP(A18,data!I:S,2,FALSE) -> Pos Y | C18: =TRUNC(VLOOKUP(A18,data!I:S,3,FALSE),1) -> -328.5 | D18: =TRUNC(VLOOKUP(A18,data!I:S,4,FALSE),1) -> -326 | E18: =VLOOKUP(A18,data!I:S,5,FALSE) -> -3 | F18: =VLOOKUP(A18,data!I:S,6,FALSE) -> 3 | G18: =C18-D18 -> -2.5 | H18: =IF(OR(G18<E18,G18>F18),1,0) -> 0 | I18: =IF(H18=1,IF(G18<E18,G18-E18,G18-F18),"") | J18: =VLOOKUP(A18,data!I:S,9,FALSE) -> Inboard Nut LH - Pos Y | X18: =IF(AND(H18=1,Y18="TRUE"),TRUE,"") | Y18: =VLOOKUP(A18,data!I:S,10,FALSE) -> TRUE | Z18: =VLOOKUP(A18,data!I:S,7,FALSE) -> -4.5 | AA18: =VLOOKUP(A18,data!I:S,8,FALSE) -> 4.5 | AB18: =IF(OR(G18<Z18,G18>AA18),TRUE,FALSE) -> FALSE
A19: FA01_01L_Z | B19: =VLOOKUP(A19,data!I:S,2,FALSE) -> Pos Z | C19: =TRUNC(VLOOKUP(A19,data!I:S,3,FALSE),1) -> 989.1 | D19: =TRUNC(VLOOKUP(A19,data!I:S,4,FALSE),1) -> 990.2 | E19: =VLOOKUP(A19,data!I:S,5,FALSE) -> -3 | F19: =VLOOKUP(A19,data!I:S,6,FALSE) -> 3 | G19: =C19-D19 -> -1.1 | H19: =IF(OR(G19<E19,G19>F19),1,0) -> 0 | I19: =IF(H19=1,IF(G19<E19,G19-E19,G19-F19),"") | J19: =VLOOKUP(A19,data!I:S,9,FALSE) -> Inboard Nut LH - Pos Z | X19: =IF(AND(H19=1,Y19="TRUE"),TRUE,"") | Y19: =VLOOKUP(A19,data!I:S,10,FALSE) -> TRUE | Z19: =VLOOKUP(A19,data!I:S,7,FALSE) -> -4.5 | AA19: =VLOOKUP(A19,data!I:S,8,FALSE) -> 4.5 | AB19: =IF(OR(G19<Z19,G19>AA19),TRUE,FALSE) -> FALSE
A20: FA01_02L_X | B20: =VLOOKUP(A20,data!I:S,2,FALSE) -> Pos X | C20: =TRUNC(VLOOKUP(A20,data!I:S,3,FALSE),1) -> 226.7 | D20: =TRUNC(VLOOKUP(A20,data!I:S,4,FALSE),1) -> 226.2 | E20: =VLOOKUP(A20,data!I:S,5,FALSE) -> -3 | F20: =VLOOKUP(A20,data!I:S,6,FALSE) -> 3 | G20: =C20-D20 -> 0.5 | H20: =IF(OR(G20<E20,G20>F20),1,0) -> 0 | I20: =IF(H20=1,IF(G20<E20,G20-E20,G20-F20),"") | J20: =VLOOKUP(A20,data!I:S,9,FALSE) -> Outboard Nut LH - Pos X | X20: =IF(AND(H20=1,Y20="TRUE"),TRUE,"") | Y20: =VLOOKUP(A20,data!I:S,10,FALSE) -> TRUE | Z20: =VLOOKUP(A20,data!I:S,7,FALSE) -> -4.5 | AA20: =VLOOKUP(A20,data!I:S,8,FALSE) -> 4.5 | AB20: =IF(OR(G20<Z20,G20>AA20),TRUE,FALSE) -> FALSE
A21: FA01_02L_Y | B21: =VLOOKUP(A21,data!I:S,2,FALSE) -> Pos Y | C21: =TRUNC(VLOOKUP(A21,data!I:S,3,FALSE),1) -> -451.2 | D21: =TRUNC(VLOOKUP(A21,data!I:S,4,FALSE),1) -> -449 | E21: =VLOOKUP(A21,data!I:S,5,FALSE) -> -3 | F21: =VLOOKUP(A21,data!I:S,6,FALSE) -> 3 | G21: =C21-D21 -> -2.2 | H21: =IF(OR(G21<E21,G21>F21),1,0) -> 0 | I21: =IF(H21=1,IF(G21<E21,G21-E21,G21-F21),"") | J21: =VLOOKUP(A21,data!I:S,9,FALSE) -> Outboard Nut LH - Pos Y | X21: =IF(AND(H21=1,Y21="TRUE"),TRUE,"") | Y21: =VLOOKUP(A21,data!I:S,10,FALSE) -> TRUE | Z21: =VLOOKUP(A21,data!I:S,7,FALSE) -> -4.5 | AA21: =VLOOKUP(A21,data!I:S,8,FALSE) -> 4.5 | AB21: =IF(OR(G21<Z21,G21>AA21),TRUE,FALSE) -> FALSE
A22: FA01_02L_Z | B22: =VLOOKUP(A22,data!I:S,2,FALSE) -> Pos Z | C22: =TRUNC(VLOOKUP(A22,data!I:S,3,FALSE),1) -> 1050.7 | D22: =TRUNC(VLOOKUP(A22,data!I:S,4,FALSE),1) -> 1052.3 | E22: =VLOOKUP(A22,data!I:S,5,FALSE) -> -3 | F22: =VLOOKUP(A22,data!I:S,6,FALSE) -> 3 | G22: =C22-D22 -> -1.6 | H22: =IF(OR(G22<E22,G22>F22),1,0) -> 0 | I22: =IF(H22=1,IF(G22<E22,G22-E22,G22-F22),"") | J22: =VLOOKUP(A22,data!I:S,9,FALSE) -> Outboard Nut LH - Pos Z | X22: =IF(AND(H22=1,Y22="TRUE"),TRUE,"") | Y22: =VLOOKUP(A22,data!I:S,10,FALSE) -> TRUE | Z22: =VLOOKUP(A22,data!I:S,7,FALSE) -> -4.5 | AA22: =VLOOKUP(A22,data!I:S,8,FALSE) -> 4.5 | AB22: =IF(OR(G22<Z22,G22>AA22),TRUE,FALSE) -> FALSE
... A33: FA01_P3L_Z | B33: =VLOOKUP(A33,data!I:S,2,FALSE) -> Dist Z | C33: =TRUNC(VLOOKUP(A33,data!I:S,3,FALSE),1) -> 79.8 | D33: =TRUNC(VLOOKUP(A33,data!I:S,4,FALSE),1) -> 81.2 | E33: =VLOOKUP(A33,data!I:S,5,FALSE) -> -4 | F33: =VLOOKUP(A33,data!I:S,6,FALSE) -> 4 | G33: =C33-D33 -> -1.4 | H33: =IF(OR(G33<E33,G33>F33),1,0) -> 0 | I33: =IF(H33=1,IF(G33<E33,G33-E33,G33-F33),"") | J33: =VLOOKUP(A33,data!I:S,9,FALSE) -> Inboard Nut vs Cab # 1 LH - H-Pitch | X33: =IF(AND(H33=1,Y33="TRUE"),TRUE,"") | Y33: =VLOOKUP(A33,data!I:S,10,FALSE) -> TRUE | Z33: =VLOOKUP(A33,data!I:S,7,FALSE) -> -8 | AA33: =VLOOKUP(A33,data!I:S,8,FALSE) -> 8 | AB33: =IF(OR(G33<Z33,G33>AA33),TRUE,FALSE) -> FALSE
A34: =INDEX(data!D:D,MATCH(OFFSET(INDIRECT("RC",FALSE),3,0),data!I:I,0)) -> Cabs Mount (D-Cab - Cab#2 HPS)
A35: Group Image
A36: Feature Id | B36: Axis | C36: Value | D36: Nominal | E36: LIE | F36: LSE | G36: Deviation | H36: Judge | I36: OOT | J36: Description | X36: NG on Accuracy | Y36: On Accuracy | Z36: LIE (internal) | AA36: LSE (internal) | AB36: Is Rejected
A37: FA02_01R_X | B37: =VLOOKUP(A37,data!I:S,2,FALSE) -> Pos X | C37: =TRUNC(VLOOKUP(A37,data!I:S,3,FALSE),1) -> 422 | D37: =TRUNC(VLOOKUP(A37,data!I:S,4,FALSE),1) -> 420 | E37: =VLOOKUP(A37,data!I:S,5,FALSE) -> -4 | F37: =VLOOKUP(A37,data!I:S,6,FALSE) -> 4 | G37: =C37-D37 -> 2 | H37: =IF(OR(G37<E37,G37>F37),1,0) -> 0 | I37: =IF(H37=1,IF(G37<E37,G37-E37,G37-F37),"") | J37: =VLOOKUP(A37,data!I:S,9,FALSE) -> Cab # 1 RH - Pos X | X37: =IF(AND(H37=1,Y37="TRUE"),TRUE,"") | Y37: =VLOOKUP(A37,data!I:S,10,FALSE) -> TRUE | Z37: =VLOOKUP(A37,data!I:S,7,FALSE) -> -8 | AA37: =VLOOKUP(A37,data!I:S,8,FALSE) -> 8 | AB37: =IF(OR(G37<Z37,G37>AA37),TRUE,FALSE) -> FALSE
A38: FA02_01R_Y | B38: =VLOOKUP(A38,data!I:S,2,FALSE) -> Pos Y | C38: =TRUNC(VLOOKUP(A38,data!I:S,3,FALSE),1) -> 459.7 | D38: =TRUNC(VLOOKUP(A38,data!I:S,4,FALSE),1) -> 459.6 | E38: =VLOOKUP(A38,data!I:S,5,FALSE) -> -4 | F38: =VLOOKUP(A38,data!I:S,6,FALSE) -> 4 | G38: =C38-D38 -> 0.1 | H38: =IF(OR(G38<E38,G38>F38),1,0) -> 0 | I38: =IF(H38=1,IF(G38<E38,G38-E38,G38-F38),"") | J38: =VLOOKUP(A38,data!I:S,9,FALSE) -> Cab # 1 RH - Pos Y | X38: =IF(AND(H38=1,Y38="TRUE"),TRUE,"") | Y38: =VLOOKUP(A38,data!I:S,10,FALSE) -> TRUE | Z38: =VLOOKUP(A38,data!I:S,7,FALSE) -> -8 | AA38: =VLOOKUP(A38,data!I:S,8,FALSE) -> 8 | AB38: =IF(OR(G38<Z38,G38>AA38),TRUE,FALSE) -> FALSE
A39: FA02_01R_Z | B39: =VLOOKUP(A39,data!I:S,2,FALSE) -> Pos Z | C39: =TRUNC(VLOOKUP(A39,data!I:S,3,FALSE),1) -> 1070.3 | D39: =TRUNC(VLOOKUP(A39,data!I:S,4,FALSE),1) -> 1071.4 | E39: =VLOOKUP(A39,data!I:S,5,FALSE) -> -4 | F39: =VLOOKUP(A39,data!I:S,6,FALSE) -> 4 | G39: =C39-D39 -> -1.1 | H39: =IF(OR(G39<E39,G39>F39),1,0) -> 0 | I39: =IF(H39=1,IF(G39<E39,G39-E39,G39-F39),"") | J39: =VLOOKUP(A39,data!I:S,9,FALSE) -> Cab # 1 RH - Pos Z | X39: =IF(AND(H39=1,Y39="TRUE"),TRUE,"") | Y39: =VLOOKUP(A39,data!I:S,10,FALSE) -> TRUE | Z39: =VLOOKUP(A39,data!I:S,7,FALSE) -> -8 | AA39: =VLOOKUP(A39,data!I:S,8,FALSE) -> 8 | AB39: =IF(OR(G39<Z39,G39>AA39),TRUE,FALSE) -> FALSE
A40: FA02_02R_X | B40: =VLOOKUP(A40,data!I:S,2,FALSE) -> Pos X | C40: =TRUNC(VLOOKUP(A40,data!I:S,3,FALSE),1) -> 1526.7 | D40: =TRUNC(VLOOKUP(A40,data!I:S,4,FALSE),1) -> 1527.1 | E40: =VLOOKUP(A40,data!I:S,5,FALSE) -> -4 | F40: =VLOOKUP(A40,data!I:S,6,FALSE) -> 4 | G40: =C40-D40 -> -0.4 | H40: =IF(OR(G40<E40,G40>F40),1,0) -> 0 | I40: =IF(H40=1,IF(G40<E40,G40-E40,G40-F40),"") | J40: =VLOOKUP(A40,data!I:S,9,FALSE) -> Cab # 2 RH - Pos X | X40: =IF(AND(H40=1,Y40="TRUE"),TRUE,"") | Y40: =VLOOKUP(A40,data!I:S,10,FALSE) -> TRUE | Z40: =VLOOKUP(A40,data!I:S,7,FALSE) -> -8 | AA40: =VLOOKUP(A40,data!I:S,8,FALSE) -> 8 | AB40: =IF(OR(G40<Z40,G40>AA40),TRUE,FALSE) -> FALSE
A41: FA02_02R_Y | B41: =VLOOKUP(A41,data!I:S,2,FALSE) -> Pos Y | C41: =TRUNC(VLOOKUP(A41,data!I:S,3,FALSE),1) -> 620.6 | D41: =TRUNC(VLOOKUP(A41,data!I:S,4,FALSE),1) -> 620.4 | E41: =VLOOKUP(A41,data!I:S,5,FALSE) -> -4 | F41: =VLOOKUP(A41,data!I:S,6,FALSE) -> 4 | G41: =C41-D41 -> 0.2 | H41: =IF(OR(G41<E41,G41>F41),1,0) -> 0 | I41: =IF(H41=1,IF(G41<E41,G41-E41,G41-F41),"") | J41: =VLOOKUP(A41,data!I:S,9,FALSE) -> Cab # 2 RH - Pos Y | X41: =IF(AND(H41=1,Y41="TRUE"),TRUE,"") | Y41: =VLOOKUP(A41,data!I:S,10,FALSE) -> TRUE | Z41: =VLOOKUP(A41,data!I:S,7,FALSE) -> -8 | AA41: =VLOOKUP(A41,data!I:S,8,FALSE) -> 8 | AB41: =IF(OR(G41<Z41,G41>AA41),TRUE,FALSE) -> FALSE
A42: FA02_02R_Z | B42: =VLOOKUP(A42,data!I:S,2,FALSE) -> Pos Z | C42: =TRUNC(VLOOKUP(A42,data!I:S,3,FALSE),1) -> 918.8 | D42: =TRUNC(VLOOKUP(A42,data!I:S,4,FALSE),1) -> 918 | E42: =VLOOKUP(A42,data!I:S,5,FALSE) -> -4 | F42: =VLOOKUP(A42,data!I:S,6,FALSE) -> 4 | G42: =C42-D42 -> 0.8 | H42: =IF(OR(G42<E42,G42>F42),1,0) -> 0 | I42: =IF(H42=1,IF(G42<E42,G42-E42,G42-F42),"") | J42: =VLOOKUP(A42,data!I:S,9,FALSE) -> Cab # 2 RH - Pos Z | X42: =IF(AND(H42=1,Y42="TRUE"),TRUE,"") | Y42: =VLOOKUP(A42,data!I:S,10,FALSE) -> TRUE | Z42: =VLOOKUP(A42,data!I:S,7,FALSE) -> -8 | AA42: =VLOOKUP(A42,data!I:S,8,FALSE) -> 8 | AB42: =IF(OR(G42<Z42,G42>AA42),TRUE,FALSE) -> FALSE
A43: FA02_01L_X | B43: =VLOOKUP(A43,data!I:S,2,FALSE) -> Pos X | C43: =TRUNC(VLOOKUP(A43,data!I:S,3,FALSE),1) -> 420.5 | D43: =TRUNC(VLOOKUP(A43,data!I:S,4,FALSE),1) -> 420 | E43: =VLOOKUP(A43,data!I:S,5,FALSE) -> -4 | F43: =VLOOKUP(A43,data!I:S,6,FALSE) -> 4 | G43: =C43-D43 -> 0.5 | H43: =IF(OR(G43<E43,G43>F43),1,0) -> 0 | I43: =IF(H43=1,IF(G43<E43,G43-E43,G43-F43),"") | J43: =VLOOKUP(A43,data!I:S,9,FALSE) -> Cab # 1 LH - Pos X | X43: =IF(AND(H43=1,Y43="TRUE"),TRUE,"") | Y43: =VLOOKUP(A43,data!I:S,10,FALSE) -> TRUE | Z43: =VLOOKUP(A43,data!I:S,7,FALSE) -> -8 | AA43: =VLOOKUP(A43,data!I:S,8,FALSE) -> 8 | AB43: =IF(OR(G43<Z43,G43>AA43),TRUE,FALSE) -> FALSE
A44: FA02_01L_Y | B44: =VLOOKUP(A44,data!I:S,2,FALSE) -> Pos Y | C44: =TRUNC(VLOOKUP(A44,data!I:S,3,FALSE),1) -> -461.3 | D44: =TRUNC(VLOOKUP(A44,data!I:S,4,FALSE),1) -> -459.6 | E44: =VLOOKUP(A44,data!I:S,5,FALSE) -> -4 | F44: =VLOOKUP(A44,data!I:S,6,FALSE) -> 4 | G44: =C44-D44 -> -1.7 | H44: =IF(OR(G44<E44,G44>F44),1,0) -> 0 | I44: =IF(H44=1,IF(G44<E44,G44-E44,G44-F44),"") | J44: =VLOOKUP(A44,data!I:S,9,FALSE) -> Cab # 1 LH - Pos Y | X44: =IF(AND(H44=1,Y44="TRUE"),TRUE,"") | Y44: =VLOOKUP(A44,data!I:S,10,FALSE) -> TRUE | Z44: =VLOOKUP(A44,data!I:S,7,FALSE) -> -8 | AA44: =VLOOKUP(A44,data!I:S,8,FALSE) -> 8 | AB44: =IF(OR(G44<Z44,G44>AA44),TRUE,FALSE) -> FALSE
A45: FA02_01L_Z | B45: =VLOOKUP(A45,data!I:S,2,FALSE) -> Pos Z | C45: =TRUNC(VLOOKUP(A45,data!I:S,3,FALSE),1) -> 1069 | D45: =TRUNC(VLOOKUP(A45,data!I:S,4,FALSE),1) -> 1071.4 | E45: =VLOOKUP(A45,data!I:S,5,FALSE) -> -4 | F45: =VLOOKUP(A45,data!I:S,6,FALSE) -> 4 | G45: =C45-D45 -> -2.4 | H45: =IF(OR(G45<E45,G45>F45),1,0) -> 0 | I45: =IF(H45=1,IF(G45<E45,G45-E45,G45-F45),"") | J45: =VLOOKUP(A45,data!I:S,9,FALSE) -> Cab # 1 LH - Pos Z | X45: =IF(AND(H45=1,Y45="TRUE"),TRUE,"") | Y45: =VLOOKUP(A45,data!I:S,10,FALSE) -> TRUE | Z45: =VLOOKUP(A45,data!I:S,7,FALSE) -> -8 | AA45: =VLOOKUP(A45,data!I:S,8,FALSE) -> 8 | AB45: =IF(OR(G45<Z45,G45>AA45),TRUE,FALSE) -> FALSE
A46: FA02_02L_X | B46: =VLOOKUP(A46,data!I:S,2,FALSE) -> Pos X | C46: =TRUNC(VLOOKUP(A46,data!I:S,3,FALSE),1) -> 1525.7 | D46: =TRUNC(VLOOKUP(A46,data!I:S,4,FALSE),1) -> 1527.1 | E46: =VLOOKUP(A46,data!I:S,5,FALSE) -> -4 | F46: =VLOOKUP(A46,data!I:S,6,FALSE) -> 4 | G46: =C46-D46 -> -1.4 | H46: =IF(OR(G46<E46,G46>F46),1,0) -> 0 | I46: =IF(H46=1,IF(G46<E46,G46-E46,G46-F46),"") | J46: =VLOOKUP(A46,data!I:S,9,FALSE) -> Cab # 2 LH - Pos X | X46: =IF(AND(H46=1,Y46="TRUE"),TRUE,"") | Y46: =VLOOKUP(A46,data!I:S,10,FALSE) -> TRUE | Z46: =VLOOKUP(A46,data!I:S,7,FALSE) -> -8 | AA46: =VLOOKUP(A46,data!I:S,8,FALSE) -> 8 | AB46: =IF(OR(G46<Z46,G46>AA46),TRUE,FALSE) -> FALSE
A47: FA02_02L_Y | B47: =VLOOKUP(A47,data!I:S,2,FALSE) -> Pos Y | C47: =TRUNC(VLOOKUP(A47,data!I:S,3,FALSE),1) -> -622.4 | D47: =TRUNC(VLOOKUP(A47,data!I:S,4,FALSE),1) -> -620.4 | E47: =VLOOKUP(A47,data!I:S,5,FALSE) -> -4 | F47: =VLOOKUP(A47,data!I:S,6,FALSE) -> 4 | G47: =C47-D47 -> -2 | H47: =IF(OR(G47<E47,G47>F47),1,0) -> 0 | I47: =IF(H47=1,IF(G47<E47,G47-E47,G47-F47),"") | J47: =VLOOKUP(A47,data!I:S,9,FALSE) -> Cab # 2 LH - Pos Y | X47: =IF(AND(H47=1,Y47="TRUE"),TRUE,"") | Y47: =VLOOKUP(A47,data!I:S,10,FALSE) -> TRUE | Z47: =VLOOKUP(A47,data!I:S,7,FALSE) -> -8 | AA47: =VLOOKUP(A47,data!I:S,8,FALSE) -> 8 | AB47: =IF(OR(G47<Z47,G47>AA47),TRUE,FALSE) -> FALSE
A48: FA02_02L_Z | B48: =VLOOKUP(A48,data!I:S,2,FALSE) -> Pos Z | C48: =TRUNC(VLOOKUP(A48,data!I:S,3,FALSE),1) -> 918.9 | D48: =TRUNC(VLOOKUP(A48,data!I:S,4,FALSE),1) -> 918 | E48: =VLOOKUP(A48,data!I:S,5,FALSE) -> -4 | F48: =VLOOKUP(A48,data!I:S,6,FALSE) -> 4 | G48: =C48-D48 -> 0.9 | H48: =IF(OR(G48<E48,G48>F48),1,0) -> 0 | I48: =IF(H48=1,IF(G48<E48,G48-E48,G48-F48),"") | J48: =VLOOKUP(A48,data!I:S,9,FALSE) -> Cab # 2 LH - Pos Z | X48: =IF(AND(H48=1,Y48="TRUE"),TRUE,"") | Y48: =VLOOKUP(A48,data!I:S,10,FALSE) -> TRUE | Z48: =VLOOKUP(A48,data!I:S,7,FALSE) -> -8 | AA48: =VLOOKUP(A48,data!I:S,8,FALSE) -> 8 | AB48: =IF(OR(G48<Z48,G48>AA48),TRUE,FALSE) -> FALSE
... A73: FA02_P20_Z | B73: =VLOOKUP(A73,data!I:S,2,FALSE) -> Dist Z | C73: =TRUNC(VLOOKUP(A73,data!I:S,3,FALSE),1) -> 0.4 | D73: =TRUNC(VLOOKUP(A73,data!I:S,4,FALSE),1) -> 0 | E73: =VLOOKUP(A73,data!I:S,5,FALSE) -> -4 | F73: =VLOOKUP(A73,data!I:S,6,FALSE) -> 4 | G73: =C73-D73 -> 0.4 | H73: =IF(OR(G73<E73,G73>F73),1,0) -> 0 | I73: =IF(H73=1,IF(G73<E73,G73-E73,G73-F73),"") | J73: =VLOOKUP(A73,data!I:S,9,FALSE) -> B+C (P10_Z + P16_Z) | X73: =IF(AND(H73=1,Y73="TRUE"),TRUE,"") | Y73: =VLOOKUP(A73,data!I:S,10,FALSE) -> TRUE | Z73: =VLOOKUP(A73,data!I:S,7,FALSE) -> -8 | AA73: =VLOOKUP(A73,data!I:S,8,FALSE) -> 8 | AB73: =IF(OR(G73<Z73,G73>AA73),TRUE,FALSE) -> FALSE
A74: =INDEX(data!D:D,MATCH(OFFSET(INDIRECT("RC",FALSE),3,0),data!I:I,0)) -> Decks Mount (D-Cab)
A75: Group Image
A76: Feature Id | B76: Axis | C76: Value | D76: Nominal | E76: LIE | F76: LSE | G76: Deviation | H76: Judge | I76: OOT | J76: Description | X76: NG on Accuracy | Y76: On Accuracy | Z76: LIE (internal) | AA76: LSE (internal) | AB76: Is Rejected
A77: FA03_02R_X | B77: =VLOOKUP(A77,data!I:S,2,FALSE) -> Pos X | C77: =TRUNC(VLOOKUP(A77,data!I:S,3,FALSE),1) -> 4509.3 | D77: =TRUNC(VLOOKUP(A77,data!I:S,4,FALSE),1) -> 4509 | E77: =VLOOKUP(A77,data!I:S,5,FALSE) -> -4 | F77: =VLOOKUP(A77,data!I:S,6,FALSE) -> 4 | G77: =C77-D77 -> 0.3 | H77: =IF(OR(G77<E77,G77>F77),1,0) -> 0 | I77: =IF(H77=1,IF(G77<E77,G77-E77,G77-F77),"") | J77: =VLOOKUP(A77,data!I:S,9,FALSE) -> Deck # 3 RH - Pos X | X77: =IF(AND(H77=1,Y77="TRUE"),TRUE,"") | Y77: =VLOOKUP(A77,data!I:S,10,FALSE) -> TRUE | Z77: =VLOOKUP(A77,data!I:S,7,FALSE) -> -6 | AA77: =VLOOKUP(A77,data!I:S,8,FALSE) -> 6 | AB77: =IF(OR(G77<Z77,G77>AA77),TRUE,FALSE) -> FALSE
...

Sheet data
A1: report_id | B1: report_description | C1: group_id | D1: group_description | E1: Expr1004 | F1: time | G1: part_id | H1: part_number | I1: feature_id | J1: axis | K1: value | L1: nominal | M1: lie_customer | N1: lse_customer | O1: lie_internal | P1: lse_internal | Q1: feature_description | R1: on_accuracy | S1: device_id | T1: group_position | U1: feature_position
A2: FRAME_MODEL_N | B2: Frame Model N Report | C2: FA01 | D2: Front Bumper | E2: 07/06/2026 | F2: 17:41:35 | G2: 51100-KKA44 | H2: 820670 | I2: FA01_01R_X | J2: Pos X | K2: 227.84 | L2: 226.2 | M2: -3 | N2: 3 | O2: -4.5 | P2: 4.5 | Q2: Inboard Nut RH - Pos X | R2: TRUE | S2: DEA_TORO | T2: 1 | U2: 1
A3: FRAME_MODEL_N | B3: Frame Model N Report | C3: FA01 | D3: Front Bumper | E3: 07/06/2026 | F3: 17:41:35 | G3: 51100-KKA44 | H3: 820670 | I3: FA01_01R_Y | J3: Pos Y | K3: 327.39 | L3: 326 | M3: -3 | N3: 3 | O3: -4.5 | P3: 4.5 | Q3: Inboard Nut RH - Pos Y | R3: TRUE | S3: DEA_TORO | T3: 1 | U3: 2
A4: FRAME_MODEL_N | B4: Frame Model N Report | C4: FA01 | D4: Front Bumper | E4: 07/06/2026 | F4: 17:41:35 | G4: 51100-KKA44 | H4: 820670 | I4: FA01_01R_Z | J4: Pos Z | K4: 988.54 | L4: 990.2 | M4: -3 | N4: 3 | O4: -4.5 | P4: 4.5 | Q4: Inboard Nut RH - Pos Z | R4: TRUE | S4: DEA_TORO | T4: 1 | U4: 3
A5: FRAME_MODEL_N | B5: Frame Model N Report | C5: FA01 | D5: Front Bumper | E5: 07/06/2026 | F5: 17:41:35 | G5: 51100-KKA44 | H5: 820670 | I5: FA01_02R_X | J5: Pos X | K5: 228.46 | L5: 226.2 | M5: -3 | N5: 3 | O5: -4.5 | P5: 4.5 | Q5: Outboard Nut RH - Pos X | R5: TRUE | S5: DEA_TORO | T5: 1 | U5: 4
A6: FRAME_MODEL_N | B6: Frame Model N Report | C6: FA01 | D6: Front Bumper | E6: 07/06/2026 | F6: 17:41:35 | G6: 51100-KKA44 | H6: 820670 | I6: FA01_02R_Y | J6: Pos Y | K6: 449.74 | L6: 449 | M6: -3 | N6: 3 | O6: -4.5 | P6: 4.5 | Q6: Outboard Nut RH - Pos Y | R6: TRUE | S6: DEA_TORO | T6: 1 | U6: 5
A7: FRAME_MODEL_N | B7: Frame Model N Report | C7: FA01 | D7: Front Bumper | E7: 07/06/2026 | F7: 17:41:35 | G7: 51100-KKA44 | H7: 820670 | I7: FA01_02R_Z | J7: Pos Z | K7: 1051.17 | L7: 1052.3 | M7: -3 | N7: 3 | O7: -4.5 | P7: 4.5 | Q7: Outboard Nut RH - Pos Z | R7: TRUE | S7: DEA_TORO | T7: 1 | U7: 6
A8: FRAME_MODEL_N | B8: Frame Model N Report | C8: FA01 | D8: Front Bumper | E8: 07/06/2026 | F8: 17:41:35 | G8: 51100-KKA44 | H8: 820670 | I8: FA01_01L_X | J8: Pos X | K8: 226.6 | L8: 226.2 | M8: -3 | N8: 3 | O8: -4.5 | P8: 4.5 | Q8: Inboard Nut LH - Pos X | R8: TRUE | S8: DEA_TORO | T8: 1 | U8: 7
A9: FRAME_MODEL_N | B9: Frame Model N Report | C9: FA01 | D9: Front Bumper | E9: 07/06/2026 | F9: 17:41:35 | G9: 51100-KKA44 | H9: 820670 | I9: FA01_01L_Y | J9: Pos Y | K9: -328.52 | L9: -326 | M9: -3 | N9: 3 | O9: -4.5 | P9: 4.5 | Q9: Inboard Nut LH - Pos Y | R9: TRUE | S9: DEA_TORO | T9: 1 | U9: 8
A10: FRAME_MODEL_N | B10: Frame Model N Report | C10: FA01 | D10: Front Bumper | E10: 07/06/2026 | F10: 17:41:35 | G10: 51100-KKA44 | H10: 820670 | I10: FA01_01L_Z | J10: Pos Z | K10: 989.12 | L10: 990.2 | M10: -3 | N10: 3 | O10: -4.5 | P10: 4.5 | Q10: Inboard Nut LH - Pos Z | R10: TRUE | S10: DEA_TORO | T10: 1 | U10: 9
A11: FRAME_MODEL_N | B11: Frame Model N Report | C11: FA01 | D11: Front Bumper | E11: 07/06/2026 | F11: 17:41:35 | G11: 51100-KKA44 | H11: 820670 | I11: FA01_02L_X | J11: Pos X | K11: 226.79 | L11: 226.2 | M11: -3 | N11: 3 | O11: -4.5 | P11: 4.5 | Q11: Outboard Nut LH - Pos X | R11: TRUE | S11: DEA_TORO | T11: 1 | U11: 10
A12: FRAME_MODEL_N | B12: Frame Model N Report | C12: FA01 | D12: Front Bumper | E12: 07/06/2026 | F12: 17:41:35 | G12: 51100-KKA44 | H12: 820670 | I12: FA01_02L_Y | J12: Pos Y | K12: -451.2 | L12: -449 | M12: -3 | N12: 3 | O12: -4.5 | P12: 4.5 | Q12: Outboard Nut LH - Pos Y | R12: TRUE | S12: DEA_TORO | T12: 1 | U12: 11
A13: FRAME_MODEL_N | B13: Frame Model N Report | C13: FA01 | D13: Front Bumper | E13: 07/06/2026 | F13: 17:41:35 | G13: 51100-KKA44 | H13: 820670 | I13: FA01_02L_Z | J13: Pos Z | K13: 1050.77 | L13: 1052.3 | M13: -3 | N13: 3 | O13: -4.5 | P13: 4.5 | Q13: Outboard Nut LH - Pos Z | R13: TRUE | S13: DEA_TORO | T13: 1 | U13: 12
... A609: FRAME_MODEL_N | B609: Frame Model N Report | C609: EXTRA_4X4 | D609: Extra features (4X4 Only) | E609: 07/06/2026 | F609: 17:41:35 | G609: 51100-KKA44 | H609: 820670 | I609: DATUM_1_EXT_LH_Z | J609: Pos Z | K609: 1012.44 | L609: 1015 | M609: -3 | N609: 3 | O609: -6 | P609: 6 | Q609: Datum Extencion LH Z | R609: FALSE | S609: DEA_TORO | T609: 23 | U609: 30
